(0.001) 
            SELECT name, type FROM sqlite_master
            WHERE type in ('table', 'view') AND NOT name='sqlite_sequence'
            ORDER BY name; args=None
(0.000) SELECT "django_migrations"."app", "django_migrations"."name" FROM "django_migrations"; args=()
(0.001) 
            SELECT name, type FROM sqlite_master
            WHERE type in ('table', 'view') AND NOT name='sqlite_sequence'
            ORDER BY name; args=None
(0.000) SELECT "django_migrations"."app", "django_migrations"."name" FROM "django_migrations"; args=()
(0.001) 
            SELECT name, type FROM sqlite_master
            WHERE type in ('table', 'view') AND NOT name='sqlite_sequence'
            ORDER BY name; args=None
(0.000) SELECT "django_migrations"."app", "django_migrations"."name" FROM "django_migrations"; args=()
(0.000) 
            SELECT name, type FROM sqlite_master
            WHERE type in ('table', 'view') AND NOT name='sqlite_sequence'
            ORDER BY name; args=None
(0.000) SELECT "django_migrations"."app", "django_migrations"."name" FROM "django_migrations"; args=()
(0.000) 
            SELECT name, type FROM sqlite_master
            WHERE type in ('table', 'view') AND NOT name='sqlite_sequence'
            ORDER BY name; args=None
(0.000) 
            SELECT name, type FROM sqlite_master
            WHERE type in ('table', 'view') AND NOT name='sqlite_sequence'
            ORDER BY name; args=None
(0.001) SELECT "django_migrations"."app", "django_migrations"."name" FROM "django_migrations"; args=()
(0.001) SELECT "django_content_type"."id", "django_content_type"."app_label", "django_content_type"."model" FROM "django_content_type" WHERE ("django_content_type"."app_label" = 'admin' AND "django_content_type"."model" = 'logentry'); args=('admin', 'logentry')
(0.000) SELECT "auth_permission"."content_type_id", "auth_permission"."codename" FROM "auth_permission" INNER JOIN "django_content_type" ON ("auth_permission"."content_type_id" = "django_content_type"."id") WHERE "auth_permission"."content_type_id" IN (1) ORDER BY "django_content_type"."app_label" ASC, "django_content_type"."model" ASC, "auth_permission"."codename" ASC; args=(1,)
(0.000) SELECT "django_content_type"."id", "django_content_type"."app_label", "django_content_type"."model" FROM "django_content_type" WHERE "django_content_type"."app_label" = 'admin'; args=('admin',)
(0.000) SELECT "django_content_type"."id", "django_content_type"."app_label", "django_content_type"."model" FROM "django_content_type" WHERE ("django_content_type"."app_label" = 'auth' AND "django_content_type"."model" = 'permission'); args=('auth', 'permission')
(0.000) SELECT "django_content_type"."id", "django_content_type"."app_label", "django_content_type"."model" FROM "django_content_type" WHERE ("django_content_type"."app_label" = 'auth' AND "django_content_type"."model" = 'group'); args=('auth', 'group')
(0.000) SELECT "django_content_type"."id", "django_content_type"."app_label", "django_content_type"."model" FROM "django_content_type" WHERE ("django_content_type"."app_label" = 'auth' AND "django_content_type"."model" = 'user'); args=('auth', 'user')
(0.000) SELECT "auth_permission"."content_type_id", "auth_permission"."codename" FROM "auth_permission" INNER JOIN "django_content_type" ON ("auth_permission"."content_type_id" = "django_content_type"."id") WHERE "auth_permission"."content_type_id" IN (2, 3, 4) ORDER BY "django_content_type"."app_label" ASC, "django_content_type"."model" ASC, "auth_permission"."codename" ASC; args=(2, 3, 4)
(0.000) SELECT "django_content_type"."id", "django_content_type"."app_label", "django_content_type"."model" FROM "django_content_type" WHERE "django_content_type"."app_label" = 'auth'; args=('auth',)
(0.001) SELECT "django_content_type"."id", "django_content_type"."app_label", "django_content_type"."model" FROM "django_content_type" WHERE ("django_content_type"."app_label" = 'contenttypes' AND "django_content_type"."model" = 'contenttype'); args=('contenttypes', 'contenttype')
(0.000) SELECT "auth_permission"."content_type_id", "auth_permission"."codename" FROM "auth_permission" INNER JOIN "django_content_type" ON ("auth_permission"."content_type_id" = "django_content_type"."id") WHERE "auth_permission"."content_type_id" IN (5) ORDER BY "django_content_type"."app_label" ASC, "django_content_type"."model" ASC, "auth_permission"."codename" ASC; args=(5,)
(0.000) SELECT "django_content_type"."id", "django_content_type"."app_label", "django_content_type"."model" FROM "django_content_type" WHERE "django_content_type"."app_label" = 'contenttypes'; args=('contenttypes',)
(0.000) SELECT "django_content_type"."id", "django_content_type"."app_label", "django_content_type"."model" FROM "django_content_type" WHERE ("django_content_type"."app_label" = 'sessions' AND "django_content_type"."model" = 'session'); args=('sessions', 'session')
(0.000) SELECT "auth_permission"."content_type_id", "auth_permission"."codename" FROM "auth_permission" INNER JOIN "django_content_type" ON ("auth_permission"."content_type_id" = "django_content_type"."id") WHERE "auth_permission"."content_type_id" IN (6) ORDER BY "django_content_type"."app_label" ASC, "django_content_type"."model" ASC, "auth_permission"."codename" ASC; args=(6,)
(0.001) SELECT "django_content_type"."id", "django_content_type"."app_label", "django_content_type"."model" FROM "django_content_type" WHERE "django_content_type"."app_label" = 'sessions'; args=('sessions',)
(0.000) SELECT "django_content_type"."id", "django_content_type"."app_label", "django_content_type"."model" FROM "django_content_type" WHERE "django_content_type"."app_label" = 'django_extensions'; args=('django_extensions',)
(0.000) SELECT "django_content_type"."id", "django_content_type"."app_label", "django_content_type"."model" FROM "django_content_type" WHERE "django_content_type"."app_label" = 'corsheaders'; args=('corsheaders',)
(0.001) SELECT "django_content_type"."id", "django_content_type"."app_label", "django_content_type"."model" FROM "django_content_type" WHERE ("django_content_type"."app_label" = 'bar' AND "django_content_type"."model" = 'notification'); args=('bar', 'notification')
(0.000) SELECT "django_content_type"."id", "django_content_type"."app_label", "django_content_type"."model" FROM "django_content_type" WHERE ("django_content_type"."app_label" = 'bar' AND "django_content_type"."model" = 'pushstatus'); args=('bar', 'pushstatus')
(0.000) SELECT "django_content_type"."id", "django_content_type"."app_label", "django_content_type"."model" FROM "django_content_type" WHERE ("django_content_type"."app_label" = 'bar' AND "django_content_type"."model" = 'user'); args=('bar', 'user')
(0.001) SELECT "auth_permission"."content_type_id", "auth_permission"."codename" FROM "auth_permission" INNER JOIN "django_content_type" ON ("auth_permission"."content_type_id" = "django_content_type"."id") WHERE "auth_permission"."content_type_id" IN (8, 9, 7) ORDER BY "django_content_type"."app_label" ASC, "django_content_type"."model" ASC, "auth_permission"."codename" ASC; args=(8, 9, 7)
(0.000) SELECT "django_content_type"."id", "django_content_type"."app_label", "django_content_type"."model" FROM "django_content_type" WHERE "django_content_type"."app_label" = 'bar'; args=('bar',)
(0.003) 
            SELECT name, type FROM sqlite_master
            WHERE type in ('table', 'view') AND NOT name='sqlite_sequence'
            ORDER BY name; args=None
(0.000) SELECT "django_migrations"."app", "django_migrations"."name" FROM "django_migrations"; args=()
(0.001) 
            SELECT name, type FROM sqlite_master
            WHERE type in ('table', 'view') AND NOT name='sqlite_sequence'
            ORDER BY name; args=None
(0.000) SELECT "django_migrations"."app", "django_migrations"."name" FROM "django_migrations"; args=()
Exception while resolving variable 'name' in template 'unknown'.
Traceback (most recent call last):
  File "D:\virtualenv\bar\lib\site-packages\django\core\handlers\exception.py", line 34, in inner
    response = get_response(request)
  File "D:\virtualenv\bar\lib\site-packages\django\core\handlers\base.py", line 111, in _get_response
    resolver_match = resolver.resolve(request.path_info)
  File "D:\virtualenv\bar\lib\site-packages\django\urls\resolvers.py", line 520, in resolve
    raise Resolver404({'tried': tried, 'path': new_path})
django.urls.exceptions.Resolver404: {'tried': [[<URLResolver <URLPattern list> (admin:admin) 'admin/'>], [<URLResolver <module 'bar.urls' from 'D:\\beam-dev\\beam-anywhere-relay\\bar\\urls.py'> (None:None) '^api/'>], [<URLPattern 'apple-app-site-association'>], [<URLPattern 'link_user'>]], 'path': 'explorer/blocks/'}

During handling of the above exception, another exception occurred:

Traceback (most recent call last):
  File "D:\virtualenv\bar\lib\site-packages\django\template\base.py", line 829, in _resolve_lookup
    current = current[bit]
TypeError: 'URLResolver' object is not subscriptable

During handling of the above exception, another exception occurred:

Traceback (most recent call last):
  File "D:\virtualenv\bar\lib\site-packages\django\template\base.py", line 837, in _resolve_lookup
    current = getattr(current, bit)
AttributeError: 'URLResolver' object has no attribute 'name'

During handling of the above exception, another exception occurred:

Traceback (most recent call last):
  File "D:\virtualenv\bar\lib\site-packages\django\template\base.py", line 843, in _resolve_lookup
    current = current[int(bit)]
ValueError: invalid literal for int() with base 10: 'name'

During handling of the above exception, another exception occurred:

Traceback (most recent call last):
  File "D:\virtualenv\bar\lib\site-packages\django\template\base.py", line 850, in _resolve_lookup
    (bit, current))  # missing attribute
django.template.base.VariableDoesNotExist: Failed lookup for key [name] in <URLResolver <URLPattern list> (admin:admin) 'admin/'>
Exception while resolving variable 'name' in template 'unknown'.
Traceback (most recent call last):
  File "D:\virtualenv\bar\lib\site-packages\django\core\handlers\exception.py", line 34, in inner
    response = get_response(request)
  File "D:\virtualenv\bar\lib\site-packages\django\core\handlers\base.py", line 111, in _get_response
    resolver_match = resolver.resolve(request.path_info)
  File "D:\virtualenv\bar\lib\site-packages\django\urls\resolvers.py", line 520, in resolve
    raise Resolver404({'tried': tried, 'path': new_path})
django.urls.exceptions.Resolver404: {'tried': [[<URLResolver <URLPattern list> (admin:admin) 'admin/'>], [<URLResolver <module 'bar.urls' from 'D:\\beam-dev\\beam-anywhere-relay\\bar\\urls.py'> (None:None) '^api/'>], [<URLPattern 'apple-app-site-association'>], [<URLPattern 'link_user'>]], 'path': 'explorer/status/'}

During handling of the above exception, another exception occurred:

Traceback (most recent call last):
  File "D:\virtualenv\bar\lib\site-packages\django\template\base.py", line 829, in _resolve_lookup
    current = current[bit]
TypeError: 'URLResolver' object is not subscriptable

During handling of the above exception, another exception occurred:

Traceback (most recent call last):
  File "D:\virtualenv\bar\lib\site-packages\django\template\base.py", line 837, in _resolve_lookup
    current = getattr(current, bit)
AttributeError: 'URLResolver' object has no attribute 'name'

During handling of the above exception, another exception occurred:

Traceback (most recent call last):
  File "D:\virtualenv\bar\lib\site-packages\django\template\base.py", line 843, in _resolve_lookup
    current = current[int(bit)]
ValueError: invalid literal for int() with base 10: 'name'

During handling of the above exception, another exception occurred:

Traceback (most recent call last):
  File "D:\virtualenv\bar\lib\site-packages\django\template\base.py", line 850, in _resolve_lookup
    (bit, current))  # missing attribute
django.template.base.VariableDoesNotExist: Failed lookup for key [name] in <URLResolver <URLPattern list> (admin:admin) 'admin/'>
Exception while resolving variable 'name' in template 'unknown'.
Traceback (most recent call last):
  File "D:\virtualenv\bar\lib\site-packages\django\core\handlers\exception.py", line 34, in inner
    response = get_response(request)
  File "D:\virtualenv\bar\lib\site-packages\django\core\handlers\base.py", line 111, in _get_response
    resolver_match = resolver.resolve(request.path_info)
  File "D:\virtualenv\bar\lib\site-packages\django\urls\resolvers.py", line 520, in resolve
    raise Resolver404({'tried': tried, 'path': new_path})
django.urls.exceptions.Resolver404: {'tried': [[<URLResolver <URLPattern list> (admin:admin) 'admin/'>], [<URLResolver <module 'bar.urls' from 'D:\\beam-dev\\beam-anywhere-relay\\bar\\urls.py'> (None:None) '^api/'>], [<URLPattern 'apple-app-site-association'>], [<URLPattern 'link_user'>]], 'path': 'explorer/blocks/'}

During handling of the above exception, another exception occurred:

Traceback (most recent call last):
  File "D:\virtualenv\bar\lib\site-packages\django\template\base.py", line 829, in _resolve_lookup
    current = current[bit]
TypeError: 'URLResolver' object is not subscriptable

During handling of the above exception, another exception occurred:

Traceback (most recent call last):
  File "D:\virtualenv\bar\lib\site-packages\django\template\base.py", line 837, in _resolve_lookup
    current = getattr(current, bit)
AttributeError: 'URLResolver' object has no attribute 'name'

During handling of the above exception, another exception occurred:

Traceback (most recent call last):
  File "D:\virtualenv\bar\lib\site-packages\django\template\base.py", line 843, in _resolve_lookup
    current = current[int(bit)]
ValueError: invalid literal for int() with base 10: 'name'

During handling of the above exception, another exception occurred:

Traceback (most recent call last):
  File "D:\virtualenv\bar\lib\site-packages\django\template\base.py", line 850, in _resolve_lookup
    (bit, current))  # missing attribute
django.template.base.VariableDoesNotExist: Failed lookup for key [name] in <URLResolver <module 'bar.urls' from 'D:\\beam-dev\\beam-anywhere-relay\\bar\\urls.py'> (None:None) '^api/'>
Exception while resolving variable 'name' in template 'unknown'.
Traceback (most recent call last):
  File "D:\virtualenv\bar\lib\site-packages\django\core\handlers\exception.py", line 34, in inner
    response = get_response(request)
  File "D:\virtualenv\bar\lib\site-packages\django\core\handlers\base.py", line 111, in _get_response
    resolver_match = resolver.resolve(request.path_info)
  File "D:\virtualenv\bar\lib\site-packages\django\urls\resolvers.py", line 520, in resolve
    raise Resolver404({'tried': tried, 'path': new_path})
django.urls.exceptions.Resolver404: {'tried': [[<URLResolver <URLPattern list> (admin:admin) 'admin/'>], [<URLResolver <module 'bar.urls' from 'D:\\beam-dev\\beam-anywhere-relay\\bar\\urls.py'> (None:None) '^api/'>], [<URLPattern 'apple-app-site-association'>], [<URLPattern 'link_user'>]], 'path': 'explorer/status/'}

During handling of the above exception, another exception occurred:

Traceback (most recent call last):
  File "D:\virtualenv\bar\lib\site-packages\django\template\base.py", line 829, in _resolve_lookup
    current = current[bit]
TypeError: 'URLResolver' object is not subscriptable

During handling of the above exception, another exception occurred:

Traceback (most recent call last):
  File "D:\virtualenv\bar\lib\site-packages\django\template\base.py", line 837, in _resolve_lookup
    current = getattr(current, bit)
AttributeError: 'URLResolver' object has no attribute 'name'

During handling of the above exception, another exception occurred:

Traceback (most recent call last):
  File "D:\virtualenv\bar\lib\site-packages\django\template\base.py", line 843, in _resolve_lookup
    current = current[int(bit)]
ValueError: invalid literal for int() with base 10: 'name'

During handling of the above exception, another exception occurred:

Traceback (most recent call last):
  File "D:\virtualenv\bar\lib\site-packages\django\template\base.py", line 850, in _resolve_lookup
    (bit, current))  # missing attribute
django.template.base.VariableDoesNotExist: Failed lookup for key [name] in <URLResolver <module 'bar.urls' from 'D:\\beam-dev\\beam-anywhere-relay\\bar\\urls.py'> (None:None) '^api/'>
Not Found: /explorer/blocks/
Not Found: /explorer/status/
"GET /explorer/blocks/?page=1 HTTP/1.1" 404 2347
"GET /explorer/status/ HTTP/1.1" 404 2340
(0.000) 
            SELECT name, type FROM sqlite_master
            WHERE type in ('table', 'view') AND NOT name='sqlite_sequence'
            ORDER BY name; args=None
(0.000) SELECT "django_migrations"."app", "django_migrations"."name" FROM "django_migrations"; args=()
Internal Server Error: /
Traceback (most recent call last):
  File "D:\virtualenv\bar\lib\site-packages\django\core\handlers\exception.py", line 34, in inner
    response = get_response(request)
  File "D:\virtualenv\bar\lib\site-packages\django\core\handlers\base.py", line 156, in _get_response
    response = self.process_exception_by_middleware(e, request)
  File "D:\virtualenv\bar\lib\site-packages\django\core\handlers\base.py", line 154, in _get_response
    response = response.render()
  File "D:\virtualenv\bar\lib\site-packages\django\template\response.py", line 106, in render
    self.content = self.rendered_content
  File "D:\virtualenv\bar\lib\site-packages\django\template\response.py", line 81, in rendered_content
    template = self.resolve_template(self.template_name)
  File "D:\virtualenv\bar\lib\site-packages\django\template\response.py", line 63, in resolve_template
    return select_template(template, using=self.using)
  File "D:\virtualenv\bar\lib\site-packages\django\template\loader.py", line 47, in select_template
    raise TemplateDoesNotExist(', '.join(template_name_list), chain=chain)
django.template.exceptions.TemplateDoesNotExist: home.html
"GET / HTTP/1.1" 500 90721
Exception while resolving variable 'name' in template 'unknown'.
Traceback (most recent call last):
  File "D:\virtualenv\bar\lib\site-packages\django\core\handlers\exception.py", line 34, in inner
    response = get_response(request)
  File "D:\virtualenv\bar\lib\site-packages\django\core\handlers\base.py", line 111, in _get_response
    resolver_match = resolver.resolve(request.path_info)
  File "D:\virtualenv\bar\lib\site-packages\django\urls\resolvers.py", line 520, in resolve
    raise Resolver404({'tried': tried, 'path': new_path})
django.urls.exceptions.Resolver404: {'tried': [[<URLPattern '' [name='home']>], [<URLResolver <URLPattern list> (admin:admin) 'admin/'>], [<URLResolver <module 'bar.urls' from 'D:\\beam-dev\\beam-anywhere-relay\\bar\\urls.py'> (None:None) '^api/'>], [<URLPattern 'apple-app-site-association'>], [<URLPattern 'link_user'>]], 'path': 'favicon.ico'}

During handling of the above exception, another exception occurred:

Traceback (most recent call last):
  File "D:\virtualenv\bar\lib\site-packages\django\template\base.py", line 829, in _resolve_lookup
    current = current[bit]
TypeError: 'URLResolver' object is not subscriptable

During handling of the above exception, another exception occurred:

Traceback (most recent call last):
  File "D:\virtualenv\bar\lib\site-packages\django\template\base.py", line 837, in _resolve_lookup
    current = getattr(current, bit)
AttributeError: 'URLResolver' object has no attribute 'name'

During handling of the above exception, another exception occurred:

Traceback (most recent call last):
  File "D:\virtualenv\bar\lib\site-packages\django\template\base.py", line 843, in _resolve_lookup
    current = current[int(bit)]
ValueError: invalid literal for int() with base 10: 'name'

During handling of the above exception, another exception occurred:

Traceback (most recent call last):
  File "D:\virtualenv\bar\lib\site-packages\django\template\base.py", line 850, in _resolve_lookup
    (bit, current))  # missing attribute
django.template.base.VariableDoesNotExist: Failed lookup for key [name] in <URLResolver <URLPattern list> (admin:admin) 'admin/'>
Exception while resolving variable 'name' in template 'unknown'.
Traceback (most recent call last):
  File "D:\virtualenv\bar\lib\site-packages\django\core\handlers\exception.py", line 34, in inner
    response = get_response(request)
  File "D:\virtualenv\bar\lib\site-packages\django\core\handlers\base.py", line 111, in _get_response
    resolver_match = resolver.resolve(request.path_info)
  File "D:\virtualenv\bar\lib\site-packages\django\urls\resolvers.py", line 520, in resolve
    raise Resolver404({'tried': tried, 'path': new_path})
django.urls.exceptions.Resolver404: {'tried': [[<URLPattern '' [name='home']>], [<URLResolver <URLPattern list> (admin:admin) 'admin/'>], [<URLResolver <module 'bar.urls' from 'D:\\beam-dev\\beam-anywhere-relay\\bar\\urls.py'> (None:None) '^api/'>], [<URLPattern 'apple-app-site-association'>], [<URLPattern 'link_user'>]], 'path': 'favicon.ico'}

During handling of the above exception, another exception occurred:

Traceback (most recent call last):
  File "D:\virtualenv\bar\lib\site-packages\django\template\base.py", line 829, in _resolve_lookup
    current = current[bit]
TypeError: 'URLResolver' object is not subscriptable

During handling of the above exception, another exception occurred:

Traceback (most recent call last):
  File "D:\virtualenv\bar\lib\site-packages\django\template\base.py", line 837, in _resolve_lookup
    current = getattr(current, bit)
AttributeError: 'URLResolver' object has no attribute 'name'

During handling of the above exception, another exception occurred:

Traceback (most recent call last):
  File "D:\virtualenv\bar\lib\site-packages\django\template\base.py", line 843, in _resolve_lookup
    current = current[int(bit)]
ValueError: invalid literal for int() with base 10: 'name'

During handling of the above exception, another exception occurred:

Traceback (most recent call last):
  File "D:\virtualenv\bar\lib\site-packages\django\template\base.py", line 850, in _resolve_lookup
    (bit, current))  # missing attribute
django.template.base.VariableDoesNotExist: Failed lookup for key [name] in <URLResolver <module 'bar.urls' from 'D:\\beam-dev\\beam-anywhere-relay\\bar\\urls.py'> (None:None) '^api/'>
Not Found: /favicon.ico
"GET /favicon.ico HTTP/1.1" 404 2438
(0.001) 
            SELECT name, type FROM sqlite_master
            WHERE type in ('table', 'view') AND NOT name='sqlite_sequence'
            ORDER BY name; args=None
(0.000) SELECT "django_migrations"."app", "django_migrations"."name" FROM "django_migrations"; args=()
Internal Server Error: /
Traceback (most recent call last):
  File "D:\virtualenv\bar\lib\site-packages\django\core\handlers\exception.py", line 34, in inner
    response = get_response(request)
  File "D:\virtualenv\bar\lib\site-packages\django\core\handlers\base.py", line 156, in _get_response
    response = self.process_exception_by_middleware(e, request)
  File "D:\virtualenv\bar\lib\site-packages\django\core\handlers\base.py", line 154, in _get_response
    response = response.render()
  File "D:\virtualenv\bar\lib\site-packages\django\template\response.py", line 106, in render
    self.content = self.rendered_content
  File "D:\virtualenv\bar\lib\site-packages\django\template\response.py", line 81, in rendered_content
    template = self.resolve_template(self.template_name)
  File "D:\virtualenv\bar\lib\site-packages\django\template\response.py", line 63, in resolve_template
    return select_template(template, using=self.using)
  File "D:\virtualenv\bar\lib\site-packages\django\template\loader.py", line 47, in select_template
    raise TemplateDoesNotExist(', '.join(template_name_list), chain=chain)
django.template.exceptions.TemplateDoesNotExist: templates/home.html
"GET / HTTP/1.1" 500 90901
(0.000) 
            SELECT name, type FROM sqlite_master
            WHERE type in ('table', 'view') AND NOT name='sqlite_sequence'
            ORDER BY name; args=None
(0.000) SELECT "django_migrations"."app", "django_migrations"."name" FROM "django_migrations"; args=()
Internal Server Error: /
Traceback (most recent call last):
  File "D:\virtualenv\bar\lib\site-packages\django\core\handlers\exception.py", line 34, in inner
    response = get_response(request)
  File "D:\virtualenv\bar\lib\site-packages\django\core\handlers\base.py", line 156, in _get_response
    response = self.process_exception_by_middleware(e, request)
  File "D:\virtualenv\bar\lib\site-packages\django\core\handlers\base.py", line 154, in _get_response
    response = response.render()
  File "D:\virtualenv\bar\lib\site-packages\django\template\response.py", line 106, in render
    self.content = self.rendered_content
  File "D:\virtualenv\bar\lib\site-packages\django\template\response.py", line 81, in rendered_content
    template = self.resolve_template(self.template_name)
  File "D:\virtualenv\bar\lib\site-packages\django\template\response.py", line 63, in resolve_template
    return select_template(template, using=self.using)
  File "D:\virtualenv\bar\lib\site-packages\django\template\loader.py", line 47, in select_template
    raise TemplateDoesNotExist(', '.join(template_name_list), chain=chain)
django.template.exceptions.TemplateDoesNotExist: templates/home.html
"GET / HTTP/1.1" 500 90901
(0.000) 
            SELECT name, type FROM sqlite_master
            WHERE type in ('table', 'view') AND NOT name='sqlite_sequence'
            ORDER BY name; args=None
(0.000) SELECT "django_migrations"."app", "django_migrations"."name" FROM "django_migrations"; args=()
Internal Server Error: /
Traceback (most recent call last):
  File "D:\virtualenv\bar\lib\site-packages\django\core\handlers\exception.py", line 34, in inner
    response = get_response(request)
  File "D:\virtualenv\bar\lib\site-packages\django\core\handlers\base.py", line 156, in _get_response
    response = self.process_exception_by_middleware(e, request)
  File "D:\virtualenv\bar\lib\site-packages\django\core\handlers\base.py", line 154, in _get_response
    response = response.render()
  File "D:\virtualenv\bar\lib\site-packages\django\template\response.py", line 106, in render
    self.content = self.rendered_content
  File "D:\virtualenv\bar\lib\site-packages\django\template\response.py", line 81, in rendered_content
    template = self.resolve_template(self.template_name)
  File "D:\virtualenv\bar\lib\site-packages\django\template\response.py", line 63, in resolve_template
    return select_template(template, using=self.using)
  File "D:\virtualenv\bar\lib\site-packages\django\template\loader.py", line 47, in select_template
    raise TemplateDoesNotExist(', '.join(template_name_list), chain=chain)
django.template.exceptions.TemplateDoesNotExist: templates/home.html
"GET / HTTP/1.1" 500 90901
Internal Server Error: /
Traceback (most recent call last):
  File "D:\virtualenv\bar\lib\site-packages\django\core\handlers\exception.py", line 34, in inner
    response = get_response(request)
  File "D:\virtualenv\bar\lib\site-packages\django\core\handlers\base.py", line 156, in _get_response
    response = self.process_exception_by_middleware(e, request)
  File "D:\virtualenv\bar\lib\site-packages\django\core\handlers\base.py", line 154, in _get_response
    response = response.render()
  File "D:\virtualenv\bar\lib\site-packages\django\template\response.py", line 106, in render
    self.content = self.rendered_content
  File "D:\virtualenv\bar\lib\site-packages\django\template\response.py", line 81, in rendered_content
    template = self.resolve_template(self.template_name)
  File "D:\virtualenv\bar\lib\site-packages\django\template\response.py", line 63, in resolve_template
    return select_template(template, using=self.using)
  File "D:\virtualenv\bar\lib\site-packages\django\template\loader.py", line 47, in select_template
    raise TemplateDoesNotExist(', '.join(template_name_list), chain=chain)
django.template.exceptions.TemplateDoesNotExist: templates/home.html
"GET / HTTP/1.1" 500 90901
Internal Server Error: /
Traceback (most recent call last):
  File "D:\virtualenv\bar\lib\site-packages\django\core\handlers\exception.py", line 34, in inner
    response = get_response(request)
  File "D:\virtualenv\bar\lib\site-packages\django\core\handlers\base.py", line 156, in _get_response
    response = self.process_exception_by_middleware(e, request)
  File "D:\virtualenv\bar\lib\site-packages\django\core\handlers\base.py", line 154, in _get_response
    response = response.render()
  File "D:\virtualenv\bar\lib\site-packages\django\template\response.py", line 106, in render
    self.content = self.rendered_content
  File "D:\virtualenv\bar\lib\site-packages\django\template\response.py", line 81, in rendered_content
    template = self.resolve_template(self.template_name)
  File "D:\virtualenv\bar\lib\site-packages\django\template\response.py", line 63, in resolve_template
    return select_template(template, using=self.using)
  File "D:\virtualenv\bar\lib\site-packages\django\template\loader.py", line 47, in select_template
    raise TemplateDoesNotExist(', '.join(template_name_list), chain=chain)
django.template.exceptions.TemplateDoesNotExist: templates/home.html
"GET / HTTP/1.1" 500 90901
(0.000) 
            SELECT name, type FROM sqlite_master
            WHERE type in ('table', 'view') AND NOT name='sqlite_sequence'
            ORDER BY name; args=None
(0.000) SELECT "django_migrations"."app", "django_migrations"."name" FROM "django_migrations"; args=()
(0.001) 
            SELECT name, type FROM sqlite_master
            WHERE type in ('table', 'view') AND NOT name='sqlite_sequence'
            ORDER BY name; args=None
(0.000) SELECT "django_migrations"."app", "django_migrations"."name" FROM "django_migrations"; args=()
Internal Server Error: /
Traceback (most recent call last):
  File "D:\virtualenv\bar\lib\site-packages\django\core\handlers\exception.py", line 34, in inner
    response = get_response(request)
  File "D:\virtualenv\bar\lib\site-packages\django\core\handlers\base.py", line 156, in _get_response
    response = self.process_exception_by_middleware(e, request)
  File "D:\virtualenv\bar\lib\site-packages\django\core\handlers\base.py", line 154, in _get_response
    response = response.render()
  File "D:\virtualenv\bar\lib\site-packages\django\template\response.py", line 106, in render
    self.content = self.rendered_content
  File "D:\virtualenv\bar\lib\site-packages\django\template\response.py", line 81, in rendered_content
    template = self.resolve_template(self.template_name)
  File "D:\virtualenv\bar\lib\site-packages\django\template\response.py", line 63, in resolve_template
    return select_template(template, using=self.using)
  File "D:\virtualenv\bar\lib\site-packages\django\template\loader.py", line 47, in select_template
    raise TemplateDoesNotExist(', '.join(template_name_list), chain=chain)
django.template.exceptions.TemplateDoesNotExist: home.html
"GET / HTTP/1.1" 500 90721
Internal Server Error: /
Traceback (most recent call last):
  File "D:\virtualenv\bar\lib\site-packages\django\core\handlers\exception.py", line 34, in inner
    response = get_response(request)
  File "D:\virtualenv\bar\lib\site-packages\django\core\handlers\base.py", line 156, in _get_response
    response = self.process_exception_by_middleware(e, request)
  File "D:\virtualenv\bar\lib\site-packages\django\core\handlers\base.py", line 154, in _get_response
    response = response.render()
  File "D:\virtualenv\bar\lib\site-packages\django\template\response.py", line 106, in render
    self.content = self.rendered_content
  File "D:\virtualenv\bar\lib\site-packages\django\template\response.py", line 81, in rendered_content
    template = self.resolve_template(self.template_name)
  File "D:\virtualenv\bar\lib\site-packages\django\template\response.py", line 63, in resolve_template
    return select_template(template, using=self.using)
  File "D:\virtualenv\bar\lib\site-packages\django\template\loader.py", line 47, in select_template
    raise TemplateDoesNotExist(', '.join(template_name_list), chain=chain)
django.template.exceptions.TemplateDoesNotExist: home.html
"GET / HTTP/1.1" 500 90721
Internal Server Error: /
Traceback (most recent call last):
  File "D:\virtualenv\bar\lib\site-packages\django\core\handlers\exception.py", line 34, in inner
    response = get_response(request)
  File "D:\virtualenv\bar\lib\site-packages\django\core\handlers\base.py", line 156, in _get_response
    response = self.process_exception_by_middleware(e, request)
  File "D:\virtualenv\bar\lib\site-packages\django\core\handlers\base.py", line 154, in _get_response
    response = response.render()
  File "D:\virtualenv\bar\lib\site-packages\django\template\response.py", line 106, in render
    self.content = self.rendered_content
  File "D:\virtualenv\bar\lib\site-packages\django\template\response.py", line 81, in rendered_content
    template = self.resolve_template(self.template_name)
  File "D:\virtualenv\bar\lib\site-packages\django\template\response.py", line 63, in resolve_template
    return select_template(template, using=self.using)
  File "D:\virtualenv\bar\lib\site-packages\django\template\loader.py", line 47, in select_template
    raise TemplateDoesNotExist(', '.join(template_name_list), chain=chain)
django.template.exceptions.TemplateDoesNotExist: home.html
"GET / HTTP/1.1" 500 90721
(0.001) 
            SELECT name, type FROM sqlite_master
            WHERE type in ('table', 'view') AND NOT name='sqlite_sequence'
            ORDER BY name; args=None
(0.000) SELECT "django_migrations"."app", "django_migrations"."name" FROM "django_migrations"; args=()
Internal Server Error: /
Traceback (most recent call last):
  File "D:\virtualenv\bar\lib\site-packages\django\core\handlers\exception.py", line 34, in inner
    response = get_response(request)
  File "D:\virtualenv\bar\lib\site-packages\django\core\handlers\base.py", line 156, in _get_response
    response = self.process_exception_by_middleware(e, request)
  File "D:\virtualenv\bar\lib\site-packages\django\core\handlers\base.py", line 154, in _get_response
    response = response.render()
  File "D:\virtualenv\bar\lib\site-packages\django\template\response.py", line 106, in render
    self.content = self.rendered_content
  File "D:\virtualenv\bar\lib\site-packages\django\template\response.py", line 81, in rendered_content
    template = self.resolve_template(self.template_name)
  File "D:\virtualenv\bar\lib\site-packages\django\template\response.py", line 63, in resolve_template
    return select_template(template, using=self.using)
  File "D:\virtualenv\bar\lib\site-packages\django\template\loader.py", line 47, in select_template
    raise TemplateDoesNotExist(', '.join(template_name_list), chain=chain)
django.template.exceptions.TemplateDoesNotExist: home.html
"GET / HTTP/1.1" 500 90721
Internal Server Error: /
Traceback (most recent call last):
  File "D:\virtualenv\bar\lib\site-packages\django\core\handlers\exception.py", line 34, in inner
    response = get_response(request)
  File "D:\virtualenv\bar\lib\site-packages\django\core\handlers\base.py", line 156, in _get_response
    response = self.process_exception_by_middleware(e, request)
  File "D:\virtualenv\bar\lib\site-packages\django\core\handlers\base.py", line 154, in _get_response
    response = response.render()
  File "D:\virtualenv\bar\lib\site-packages\django\template\response.py", line 106, in render
    self.content = self.rendered_content
  File "D:\virtualenv\bar\lib\site-packages\django\template\response.py", line 81, in rendered_content
    template = self.resolve_template(self.template_name)
  File "D:\virtualenv\bar\lib\site-packages\django\template\response.py", line 63, in resolve_template
    return select_template(template, using=self.using)
  File "D:\virtualenv\bar\lib\site-packages\django\template\loader.py", line 47, in select_template
    raise TemplateDoesNotExist(', '.join(template_name_list), chain=chain)
django.template.exceptions.TemplateDoesNotExist: home.html
"GET / HTTP/1.1" 500 90721
Internal Server Error: /
Traceback (most recent call last):
  File "D:\virtualenv\bar\lib\site-packages\django\core\handlers\exception.py", line 34, in inner
    response = get_response(request)
  File "D:\virtualenv\bar\lib\site-packages\django\core\handlers\base.py", line 156, in _get_response
    response = self.process_exception_by_middleware(e, request)
  File "D:\virtualenv\bar\lib\site-packages\django\core\handlers\base.py", line 154, in _get_response
    response = response.render()
  File "D:\virtualenv\bar\lib\site-packages\django\template\response.py", line 106, in render
    self.content = self.rendered_content
  File "D:\virtualenv\bar\lib\site-packages\django\template\response.py", line 81, in rendered_content
    template = self.resolve_template(self.template_name)
  File "D:\virtualenv\bar\lib\site-packages\django\template\response.py", line 63, in resolve_template
    return select_template(template, using=self.using)
  File "D:\virtualenv\bar\lib\site-packages\django\template\loader.py", line 47, in select_template
    raise TemplateDoesNotExist(', '.join(template_name_list), chain=chain)
django.template.exceptions.TemplateDoesNotExist: home.html
"GET / HTTP/1.1" 500 90721
(0.000) 
            SELECT name, type FROM sqlite_master
            WHERE type in ('table', 'view') AND NOT name='sqlite_sequence'
            ORDER BY name; args=None
(0.000) SELECT "django_migrations"."app", "django_migrations"."name" FROM "django_migrations"; args=()
"GET / HTTP/1.1" 200 18
"GET / HTTP/1.1" 200 538
"GET / HTTP/1.1" 200 520
"GET / HTTP/1.1" 200 551
"GET / HTTP/1.1" 200 551
"GET / HTTP/1.1" 200 551
"GET / HTTP/1.1" 200 596
"GET / HTTP/1.1" 200 653
"GET / HTTP/1.1" 200 677
"GET / HTTP/1.1" 200 685
"GET / HTTP/1.1" 200 698
"GET / HTTP/1.1" 200 724
"GET / HTTP/1.1" 200 726
"GET / HTTP/1.1" 200 713
"GET / HTTP/1.1" 200 736
"GET / HTTP/1.1" 200 750
"GET / HTTP/1.1" 200 801
"GET / HTTP/1.1" 200 801
"GET / HTTP/1.1" 200 841
"GET / HTTP/1.1" 200 878
"GET / HTTP/1.1" 200 865
"GET / HTTP/1.1" 200 865
"GET / HTTP/1.1" 200 865
"GET / HTTP/1.1" 200 935
Exception while resolving variable 'name' in template 'unknown'.
Traceback (most recent call last):
  File "D:\virtualenv\bar\lib\site-packages\django\core\handlers\exception.py", line 34, in inner
    response = get_response(request)
  File "D:\virtualenv\bar\lib\site-packages\django\core\handlers\base.py", line 111, in _get_response
    resolver_match = resolver.resolve(request.path_info)
  File "D:\virtualenv\bar\lib\site-packages\django\urls\resolvers.py", line 520, in resolve
    raise Resolver404({'tried': tried, 'path': new_path})
django.urls.exceptions.Resolver404: {'tried': [[<URLPattern '' [name='home']>], [<URLResolver <URLPattern list> (admin:admin) 'admin/'>], [<URLResolver <module 'bar.urls' from 'D:\\beam-dev\\beam-anywhere-relay\\bar\\urls.py'> (None:None) '^api/'>], [<URLPattern 'apple-app-site-association'>], [<URLPattern 'link_user'>]], 'path': 'logo.svg'}

During handling of the above exception, another exception occurred:

Traceback (most recent call last):
  File "D:\virtualenv\bar\lib\site-packages\django\template\base.py", line 829, in _resolve_lookup
    current = current[bit]
TypeError: 'URLResolver' object is not subscriptable

During handling of the above exception, another exception occurred:

Traceback (most recent call last):
  File "D:\virtualenv\bar\lib\site-packages\django\template\base.py", line 837, in _resolve_lookup
    current = getattr(current, bit)
AttributeError: 'URLResolver' object has no attribute 'name'

During handling of the above exception, another exception occurred:

Traceback (most recent call last):
  File "D:\virtualenv\bar\lib\site-packages\django\template\base.py", line 843, in _resolve_lookup
    current = current[int(bit)]
ValueError: invalid literal for int() with base 10: 'name'

During handling of the above exception, another exception occurred:

Traceback (most recent call last):
  File "D:\virtualenv\bar\lib\site-packages\django\template\base.py", line 850, in _resolve_lookup
    (bit, current))  # missing attribute
django.template.base.VariableDoesNotExist: Failed lookup for key [name] in <URLResolver <URLPattern list> (admin:admin) 'admin/'>
Exception while resolving variable 'name' in template 'unknown'.
Traceback (most recent call last):
  File "D:\virtualenv\bar\lib\site-packages\django\core\handlers\exception.py", line 34, in inner
    response = get_response(request)
  File "D:\virtualenv\bar\lib\site-packages\django\core\handlers\base.py", line 111, in _get_response
    resolver_match = resolver.resolve(request.path_info)
  File "D:\virtualenv\bar\lib\site-packages\django\urls\resolvers.py", line 520, in resolve
    raise Resolver404({'tried': tried, 'path': new_path})
django.urls.exceptions.Resolver404: {'tried': [[<URLPattern '' [name='home']>], [<URLResolver <URLPattern list> (admin:admin) 'admin/'>], [<URLResolver <module 'bar.urls' from 'D:\\beam-dev\\beam-anywhere-relay\\bar\\urls.py'> (None:None) '^api/'>], [<URLPattern 'apple-app-site-association'>], [<URLPattern 'link_user'>]], 'path': 'logo.svg'}

During handling of the above exception, another exception occurred:

Traceback (most recent call last):
  File "D:\virtualenv\bar\lib\site-packages\django\template\base.py", line 829, in _resolve_lookup
    current = current[bit]
TypeError: 'URLResolver' object is not subscriptable

During handling of the above exception, another exception occurred:

Traceback (most recent call last):
  File "D:\virtualenv\bar\lib\site-packages\django\template\base.py", line 837, in _resolve_lookup
    current = getattr(current, bit)
AttributeError: 'URLResolver' object has no attribute 'name'

During handling of the above exception, another exception occurred:

Traceback (most recent call last):
  File "D:\virtualenv\bar\lib\site-packages\django\template\base.py", line 843, in _resolve_lookup
    current = current[int(bit)]
ValueError: invalid literal for int() with base 10: 'name'

During handling of the above exception, another exception occurred:

Traceback (most recent call last):
  File "D:\virtualenv\bar\lib\site-packages\django\template\base.py", line 850, in _resolve_lookup
    (bit, current))  # missing attribute
django.template.base.VariableDoesNotExist: Failed lookup for key [name] in <URLResolver <module 'bar.urls' from 'D:\\beam-dev\\beam-anywhere-relay\\bar\\urls.py'> (None:None) '^api/'>
Not Found: /logo.svg
"GET /logo.svg HTTP/1.1" 404 2429
"GET / HTTP/1.1" 200 937
Exception while resolving variable 'name' in template 'unknown'.
Traceback (most recent call last):
  File "D:\virtualenv\bar\lib\site-packages\django\core\handlers\exception.py", line 34, in inner
    response = get_response(request)
  File "D:\virtualenv\bar\lib\site-packages\django\core\handlers\base.py", line 111, in _get_response
    resolver_match = resolver.resolve(request.path_info)
  File "D:\virtualenv\bar\lib\site-packages\django\urls\resolvers.py", line 520, in resolve
    raise Resolver404({'tried': tried, 'path': new_path})
django.urls.exceptions.Resolver404: {'tried': [[<URLPattern '' [name='home']>], [<URLResolver <URLPattern list> (admin:admin) 'admin/'>], [<URLResolver <module 'bar.urls' from 'D:\\beam-dev\\beam-anywhere-relay\\bar\\urls.py'> (None:None) '^api/'>], [<URLPattern 'apple-app-site-association'>], [<URLPattern 'link_user'>]], 'path': 'logo.svg'}

During handling of the above exception, another exception occurred:

Traceback (most recent call last):
  File "D:\virtualenv\bar\lib\site-packages\django\template\base.py", line 829, in _resolve_lookup
    current = current[bit]
TypeError: 'URLResolver' object is not subscriptable

During handling of the above exception, another exception occurred:

Traceback (most recent call last):
  File "D:\virtualenv\bar\lib\site-packages\django\template\base.py", line 837, in _resolve_lookup
    current = getattr(current, bit)
AttributeError: 'URLResolver' object has no attribute 'name'

During handling of the above exception, another exception occurred:

Traceback (most recent call last):
  File "D:\virtualenv\bar\lib\site-packages\django\template\base.py", line 843, in _resolve_lookup
    current = current[int(bit)]
ValueError: invalid literal for int() with base 10: 'name'

During handling of the above exception, another exception occurred:

Traceback (most recent call last):
  File "D:\virtualenv\bar\lib\site-packages\django\template\base.py", line 850, in _resolve_lookup
    (bit, current))  # missing attribute
django.template.base.VariableDoesNotExist: Failed lookup for key [name] in <URLResolver <URLPattern list> (admin:admin) 'admin/'>
Exception while resolving variable 'name' in template 'unknown'.
Traceback (most recent call last):
  File "D:\virtualenv\bar\lib\site-packages\django\core\handlers\exception.py", line 34, in inner
    response = get_response(request)
  File "D:\virtualenv\bar\lib\site-packages\django\core\handlers\base.py", line 111, in _get_response
    resolver_match = resolver.resolve(request.path_info)
  File "D:\virtualenv\bar\lib\site-packages\django\urls\resolvers.py", line 520, in resolve
    raise Resolver404({'tried': tried, 'path': new_path})
django.urls.exceptions.Resolver404: {'tried': [[<URLPattern '' [name='home']>], [<URLResolver <URLPattern list> (admin:admin) 'admin/'>], [<URLResolver <module 'bar.urls' from 'D:\\beam-dev\\beam-anywhere-relay\\bar\\urls.py'> (None:None) '^api/'>], [<URLPattern 'apple-app-site-association'>], [<URLPattern 'link_user'>]], 'path': 'logo.svg'}

During handling of the above exception, another exception occurred:

Traceback (most recent call last):
  File "D:\virtualenv\bar\lib\site-packages\django\template\base.py", line 829, in _resolve_lookup
    current = current[bit]
TypeError: 'URLResolver' object is not subscriptable

During handling of the above exception, another exception occurred:

Traceback (most recent call last):
  File "D:\virtualenv\bar\lib\site-packages\django\template\base.py", line 837, in _resolve_lookup
    current = getattr(current, bit)
AttributeError: 'URLResolver' object has no attribute 'name'

During handling of the above exception, another exception occurred:

Traceback (most recent call last):
  File "D:\virtualenv\bar\lib\site-packages\django\template\base.py", line 843, in _resolve_lookup
    current = current[int(bit)]
ValueError: invalid literal for int() with base 10: 'name'

During handling of the above exception, another exception occurred:

Traceback (most recent call last):
  File "D:\virtualenv\bar\lib\site-packages\django\template\base.py", line 850, in _resolve_lookup
    (bit, current))  # missing attribute
django.template.base.VariableDoesNotExist: Failed lookup for key [name] in <URLResolver <module 'bar.urls' from 'D:\\beam-dev\\beam-anywhere-relay\\bar\\urls.py'> (None:None) '^api/'>
Not Found: /logo.svg
"GET /logo.svg HTTP/1.1" 404 2429
"GET / HTTP/1.1" 200 937
Exception while resolving variable 'name' in template 'unknown'.
Traceback (most recent call last):
  File "D:\virtualenv\bar\lib\site-packages\django\core\handlers\exception.py", line 34, in inner
    response = get_response(request)
  File "D:\virtualenv\bar\lib\site-packages\django\core\handlers\base.py", line 111, in _get_response
    resolver_match = resolver.resolve(request.path_info)
  File "D:\virtualenv\bar\lib\site-packages\django\urls\resolvers.py", line 520, in resolve
    raise Resolver404({'tried': tried, 'path': new_path})
django.urls.exceptions.Resolver404: {'tried': [[<URLPattern '' [name='home']>], [<URLResolver <URLPattern list> (admin:admin) 'admin/'>], [<URLResolver <module 'bar.urls' from 'D:\\beam-dev\\beam-anywhere-relay\\bar\\urls.py'> (None:None) '^api/'>], [<URLPattern 'apple-app-site-association'>], [<URLPattern 'link_user'>]], 'path': 'logo.svg'}

During handling of the above exception, another exception occurred:

Traceback (most recent call last):
  File "D:\virtualenv\bar\lib\site-packages\django\template\base.py", line 829, in _resolve_lookup
    current = current[bit]
TypeError: 'URLResolver' object is not subscriptable

During handling of the above exception, another exception occurred:

Traceback (most recent call last):
  File "D:\virtualenv\bar\lib\site-packages\django\template\base.py", line 837, in _resolve_lookup
    current = getattr(current, bit)
AttributeError: 'URLResolver' object has no attribute 'name'

During handling of the above exception, another exception occurred:

Traceback (most recent call last):
  File "D:\virtualenv\bar\lib\site-packages\django\template\base.py", line 843, in _resolve_lookup
    current = current[int(bit)]
ValueError: invalid literal for int() with base 10: 'name'

During handling of the above exception, another exception occurred:

Traceback (most recent call last):
  File "D:\virtualenv\bar\lib\site-packages\django\template\base.py", line 850, in _resolve_lookup
    (bit, current))  # missing attribute
django.template.base.VariableDoesNotExist: Failed lookup for key [name] in <URLResolver <URLPattern list> (admin:admin) 'admin/'>
Exception while resolving variable 'name' in template 'unknown'.
Traceback (most recent call last):
  File "D:\virtualenv\bar\lib\site-packages\django\core\handlers\exception.py", line 34, in inner
    response = get_response(request)
  File "D:\virtualenv\bar\lib\site-packages\django\core\handlers\base.py", line 111, in _get_response
    resolver_match = resolver.resolve(request.path_info)
  File "D:\virtualenv\bar\lib\site-packages\django\urls\resolvers.py", line 520, in resolve
    raise Resolver404({'tried': tried, 'path': new_path})
django.urls.exceptions.Resolver404: {'tried': [[<URLPattern '' [name='home']>], [<URLResolver <URLPattern list> (admin:admin) 'admin/'>], [<URLResolver <module 'bar.urls' from 'D:\\beam-dev\\beam-anywhere-relay\\bar\\urls.py'> (None:None) '^api/'>], [<URLPattern 'apple-app-site-association'>], [<URLPattern 'link_user'>]], 'path': 'logo.svg'}

During handling of the above exception, another exception occurred:

Traceback (most recent call last):
  File "D:\virtualenv\bar\lib\site-packages\django\template\base.py", line 829, in _resolve_lookup
    current = current[bit]
TypeError: 'URLResolver' object is not subscriptable

During handling of the above exception, another exception occurred:

Traceback (most recent call last):
  File "D:\virtualenv\bar\lib\site-packages\django\template\base.py", line 837, in _resolve_lookup
    current = getattr(current, bit)
AttributeError: 'URLResolver' object has no attribute 'name'

During handling of the above exception, another exception occurred:

Traceback (most recent call last):
  File "D:\virtualenv\bar\lib\site-packages\django\template\base.py", line 843, in _resolve_lookup
    current = current[int(bit)]
ValueError: invalid literal for int() with base 10: 'name'

During handling of the above exception, another exception occurred:

Traceback (most recent call last):
  File "D:\virtualenv\bar\lib\site-packages\django\template\base.py", line 850, in _resolve_lookup
    (bit, current))  # missing attribute
django.template.base.VariableDoesNotExist: Failed lookup for key [name] in <URLResolver <module 'bar.urls' from 'D:\\beam-dev\\beam-anywhere-relay\\bar\\urls.py'> (None:None) '^api/'>
Not Found: /logo.svg
"GET /logo.svg HTTP/1.1" 404 2429
"GET / HTTP/1.1" 200 935
Exception while resolving variable 'name' in template 'unknown'.
Traceback (most recent call last):
  File "D:\virtualenv\bar\lib\site-packages\django\core\handlers\exception.py", line 34, in inner
    response = get_response(request)
  File "D:\virtualenv\bar\lib\site-packages\django\core\handlers\base.py", line 111, in _get_response
    resolver_match = resolver.resolve(request.path_info)
  File "D:\virtualenv\bar\lib\site-packages\django\urls\resolvers.py", line 520, in resolve
    raise Resolver404({'tried': tried, 'path': new_path})
django.urls.exceptions.Resolver404: {'tried': [[<URLPattern '' [name='home']>], [<URLResolver <URLPattern list> (admin:admin) 'admin/'>], [<URLResolver <module 'bar.urls' from 'D:\\beam-dev\\beam-anywhere-relay\\bar\\urls.py'> (None:None) '^api/'>], [<URLPattern 'apple-app-site-association'>], [<URLPattern 'link_user'>]], 'path': 'logo.png'}

During handling of the above exception, another exception occurred:

Traceback (most recent call last):
  File "D:\virtualenv\bar\lib\site-packages\django\template\base.py", line 829, in _resolve_lookup
    current = current[bit]
TypeError: 'URLResolver' object is not subscriptable

During handling of the above exception, another exception occurred:

Traceback (most recent call last):
  File "D:\virtualenv\bar\lib\site-packages\django\template\base.py", line 837, in _resolve_lookup
    current = getattr(current, bit)
AttributeError: 'URLResolver' object has no attribute 'name'

During handling of the above exception, another exception occurred:

Traceback (most recent call last):
  File "D:\virtualenv\bar\lib\site-packages\django\template\base.py", line 843, in _resolve_lookup
    current = current[int(bit)]
ValueError: invalid literal for int() with base 10: 'name'

During handling of the above exception, another exception occurred:

Traceback (most recent call last):
  File "D:\virtualenv\bar\lib\site-packages\django\template\base.py", line 850, in _resolve_lookup
    (bit, current))  # missing attribute
django.template.base.VariableDoesNotExist: Failed lookup for key [name] in <URLResolver <URLPattern list> (admin:admin) 'admin/'>
Exception while resolving variable 'name' in template 'unknown'.
Traceback (most recent call last):
  File "D:\virtualenv\bar\lib\site-packages\django\core\handlers\exception.py", line 34, in inner
    response = get_response(request)
  File "D:\virtualenv\bar\lib\site-packages\django\core\handlers\base.py", line 111, in _get_response
    resolver_match = resolver.resolve(request.path_info)
  File "D:\virtualenv\bar\lib\site-packages\django\urls\resolvers.py", line 520, in resolve
    raise Resolver404({'tried': tried, 'path': new_path})
django.urls.exceptions.Resolver404: {'tried': [[<URLPattern '' [name='home']>], [<URLResolver <URLPattern list> (admin:admin) 'admin/'>], [<URLResolver <module 'bar.urls' from 'D:\\beam-dev\\beam-anywhere-relay\\bar\\urls.py'> (None:None) '^api/'>], [<URLPattern 'apple-app-site-association'>], [<URLPattern 'link_user'>]], 'path': 'logo.png'}

During handling of the above exception, another exception occurred:

Traceback (most recent call last):
  File "D:\virtualenv\bar\lib\site-packages\django\template\base.py", line 829, in _resolve_lookup
    current = current[bit]
TypeError: 'URLResolver' object is not subscriptable

During handling of the above exception, another exception occurred:

Traceback (most recent call last):
  File "D:\virtualenv\bar\lib\site-packages\django\template\base.py", line 837, in _resolve_lookup
    current = getattr(current, bit)
AttributeError: 'URLResolver' object has no attribute 'name'

During handling of the above exception, another exception occurred:

Traceback (most recent call last):
  File "D:\virtualenv\bar\lib\site-packages\django\template\base.py", line 843, in _resolve_lookup
    current = current[int(bit)]
ValueError: invalid literal for int() with base 10: 'name'

During handling of the above exception, another exception occurred:

Traceback (most recent call last):
  File "D:\virtualenv\bar\lib\site-packages\django\template\base.py", line 850, in _resolve_lookup
    (bit, current))  # missing attribute
django.template.base.VariableDoesNotExist: Failed lookup for key [name] in <URLResolver <module 'bar.urls' from 'D:\\beam-dev\\beam-anywhere-relay\\bar\\urls.py'> (None:None) '^api/'>
Not Found: /logo.png
"GET /logo.png HTTP/1.1" 404 2429
"GET / HTTP/1.1" 200 935
Exception while resolving variable 'name' in template 'unknown'.
Traceback (most recent call last):
  File "D:\virtualenv\bar\lib\site-packages\django\core\handlers\exception.py", line 34, in inner
    response = get_response(request)
  File "D:\virtualenv\bar\lib\site-packages\django\core\handlers\base.py", line 111, in _get_response
    resolver_match = resolver.resolve(request.path_info)
  File "D:\virtualenv\bar\lib\site-packages\django\urls\resolvers.py", line 520, in resolve
    raise Resolver404({'tried': tried, 'path': new_path})
django.urls.exceptions.Resolver404: {'tried': [[<URLPattern '' [name='home']>], [<URLResolver <URLPattern list> (admin:admin) 'admin/'>], [<URLResolver <module 'bar.urls' from 'D:\\beam-dev\\beam-anywhere-relay\\bar\\urls.py'> (None:None) '^api/'>], [<URLPattern 'apple-app-site-association'>], [<URLPattern 'link_user'>]], 'path': 'logo.png'}

During handling of the above exception, another exception occurred:

Traceback (most recent call last):
  File "D:\virtualenv\bar\lib\site-packages\django\template\base.py", line 829, in _resolve_lookup
    current = current[bit]
TypeError: 'URLResolver' object is not subscriptable

During handling of the above exception, another exception occurred:

Traceback (most recent call last):
  File "D:\virtualenv\bar\lib\site-packages\django\template\base.py", line 837, in _resolve_lookup
    current = getattr(current, bit)
AttributeError: 'URLResolver' object has no attribute 'name'

During handling of the above exception, another exception occurred:

Traceback (most recent call last):
  File "D:\virtualenv\bar\lib\site-packages\django\template\base.py", line 843, in _resolve_lookup
    current = current[int(bit)]
ValueError: invalid literal for int() with base 10: 'name'

During handling of the above exception, another exception occurred:

Traceback (most recent call last):
  File "D:\virtualenv\bar\lib\site-packages\django\template\base.py", line 850, in _resolve_lookup
    (bit, current))  # missing attribute
django.template.base.VariableDoesNotExist: Failed lookup for key [name] in <URLResolver <URLPattern list> (admin:admin) 'admin/'>
Exception while resolving variable 'name' in template 'unknown'.
Traceback (most recent call last):
  File "D:\virtualenv\bar\lib\site-packages\django\core\handlers\exception.py", line 34, in inner
    response = get_response(request)
  File "D:\virtualenv\bar\lib\site-packages\django\core\handlers\base.py", line 111, in _get_response
    resolver_match = resolver.resolve(request.path_info)
  File "D:\virtualenv\bar\lib\site-packages\django\urls\resolvers.py", line 520, in resolve
    raise Resolver404({'tried': tried, 'path': new_path})
django.urls.exceptions.Resolver404: {'tried': [[<URLPattern '' [name='home']>], [<URLResolver <URLPattern list> (admin:admin) 'admin/'>], [<URLResolver <module 'bar.urls' from 'D:\\beam-dev\\beam-anywhere-relay\\bar\\urls.py'> (None:None) '^api/'>], [<URLPattern 'apple-app-site-association'>], [<URLPattern 'link_user'>]], 'path': 'logo.png'}

During handling of the above exception, another exception occurred:

Traceback (most recent call last):
  File "D:\virtualenv\bar\lib\site-packages\django\template\base.py", line 829, in _resolve_lookup
    current = current[bit]
TypeError: 'URLResolver' object is not subscriptable

During handling of the above exception, another exception occurred:

Traceback (most recent call last):
  File "D:\virtualenv\bar\lib\site-packages\django\template\base.py", line 837, in _resolve_lookup
    current = getattr(current, bit)
AttributeError: 'URLResolver' object has no attribute 'name'

During handling of the above exception, another exception occurred:

Traceback (most recent call last):
  File "D:\virtualenv\bar\lib\site-packages\django\template\base.py", line 843, in _resolve_lookup
    current = current[int(bit)]
ValueError: invalid literal for int() with base 10: 'name'

During handling of the above exception, another exception occurred:

Traceback (most recent call last):
  File "D:\virtualenv\bar\lib\site-packages\django\template\base.py", line 850, in _resolve_lookup
    (bit, current))  # missing attribute
django.template.base.VariableDoesNotExist: Failed lookup for key [name] in <URLResolver <module 'bar.urls' from 'D:\\beam-dev\\beam-anywhere-relay\\bar\\urls.py'> (None:None) '^api/'>
Not Found: /logo.png
"GET /logo.png HTTP/1.1" 404 2429
(0.001) 
            SELECT name, type FROM sqlite_master
            WHERE type in ('table', 'view') AND NOT name='sqlite_sequence'
            ORDER BY name; args=None
(0.000) SELECT "django_migrations"."app", "django_migrations"."name" FROM "django_migrations"; args=()
"GET / HTTP/1.1" 200 935
Exception while resolving variable 'name' in template 'unknown'.
Traceback (most recent call last):
  File "D:\virtualenv\bar\lib\site-packages\django\core\handlers\exception.py", line 34, in inner
    response = get_response(request)
  File "D:\virtualenv\bar\lib\site-packages\django\core\handlers\base.py", line 111, in _get_response
    resolver_match = resolver.resolve(request.path_info)
  File "D:\virtualenv\bar\lib\site-packages\django\urls\resolvers.py", line 520, in resolve
    raise Resolver404({'tried': tried, 'path': new_path})
django.urls.exceptions.Resolver404: {'tried': [[<URLPattern '' [name='home']>], [<URLResolver <URLPattern list> (admin:admin) 'admin/'>], [<URLResolver <module 'bar.urls' from 'D:\\beam-dev\\beam-anywhere-relay\\bar\\urls.py'> (None:None) '^api/'>], [<URLPattern 'apple-app-site-association'>], [<URLPattern 'link_user'>]], 'path': 'logo.png'}

During handling of the above exception, another exception occurred:

Traceback (most recent call last):
  File "D:\virtualenv\bar\lib\site-packages\django\template\base.py", line 829, in _resolve_lookup
    current = current[bit]
TypeError: 'URLResolver' object is not subscriptable

During handling of the above exception, another exception occurred:

Traceback (most recent call last):
  File "D:\virtualenv\bar\lib\site-packages\django\template\base.py", line 837, in _resolve_lookup
    current = getattr(current, bit)
AttributeError: 'URLResolver' object has no attribute 'name'

During handling of the above exception, another exception occurred:

Traceback (most recent call last):
  File "D:\virtualenv\bar\lib\site-packages\django\template\base.py", line 843, in _resolve_lookup
    current = current[int(bit)]
ValueError: invalid literal for int() with base 10: 'name'

During handling of the above exception, another exception occurred:

Traceback (most recent call last):
  File "D:\virtualenv\bar\lib\site-packages\django\template\base.py", line 850, in _resolve_lookup
    (bit, current))  # missing attribute
django.template.base.VariableDoesNotExist: Failed lookup for key [name] in <URLResolver <URLPattern list> (admin:admin) 'admin/'>
Exception while resolving variable 'name' in template 'unknown'.
Traceback (most recent call last):
  File "D:\virtualenv\bar\lib\site-packages\django\core\handlers\exception.py", line 34, in inner
    response = get_response(request)
  File "D:\virtualenv\bar\lib\site-packages\django\core\handlers\base.py", line 111, in _get_response
    resolver_match = resolver.resolve(request.path_info)
  File "D:\virtualenv\bar\lib\site-packages\django\urls\resolvers.py", line 520, in resolve
    raise Resolver404({'tried': tried, 'path': new_path})
django.urls.exceptions.Resolver404: {'tried': [[<URLPattern '' [name='home']>], [<URLResolver <URLPattern list> (admin:admin) 'admin/'>], [<URLResolver <module 'bar.urls' from 'D:\\beam-dev\\beam-anywhere-relay\\bar\\urls.py'> (None:None) '^api/'>], [<URLPattern 'apple-app-site-association'>], [<URLPattern 'link_user'>]], 'path': 'logo.png'}

During handling of the above exception, another exception occurred:

Traceback (most recent call last):
  File "D:\virtualenv\bar\lib\site-packages\django\template\base.py", line 829, in _resolve_lookup
    current = current[bit]
TypeError: 'URLResolver' object is not subscriptable

During handling of the above exception, another exception occurred:

Traceback (most recent call last):
  File "D:\virtualenv\bar\lib\site-packages\django\template\base.py", line 837, in _resolve_lookup
    current = getattr(current, bit)
AttributeError: 'URLResolver' object has no attribute 'name'

During handling of the above exception, another exception occurred:

Traceback (most recent call last):
  File "D:\virtualenv\bar\lib\site-packages\django\template\base.py", line 843, in _resolve_lookup
    current = current[int(bit)]
ValueError: invalid literal for int() with base 10: 'name'

During handling of the above exception, another exception occurred:

Traceback (most recent call last):
  File "D:\virtualenv\bar\lib\site-packages\django\template\base.py", line 850, in _resolve_lookup
    (bit, current))  # missing attribute
django.template.base.VariableDoesNotExist: Failed lookup for key [name] in <URLResolver <module 'bar.urls' from 'D:\\beam-dev\\beam-anywhere-relay\\bar\\urls.py'> (None:None) '^api/'>
Not Found: /logo.png
"GET /logo.png HTTP/1.1" 404 2429
"GET / HTTP/1.1" 200 935
Exception while resolving variable 'name' in template 'unknown'.
Traceback (most recent call last):
  File "D:\virtualenv\bar\lib\site-packages\django\core\handlers\exception.py", line 34, in inner
    response = get_response(request)
  File "D:\virtualenv\bar\lib\site-packages\django\core\handlers\base.py", line 111, in _get_response
    resolver_match = resolver.resolve(request.path_info)
  File "D:\virtualenv\bar\lib\site-packages\django\urls\resolvers.py", line 520, in resolve
    raise Resolver404({'tried': tried, 'path': new_path})
django.urls.exceptions.Resolver404: {'tried': [[<URLPattern '' [name='home']>], [<URLResolver <URLPattern list> (admin:admin) 'admin/'>], [<URLResolver <module 'bar.urls' from 'D:\\beam-dev\\beam-anywhere-relay\\bar\\urls.py'> (None:None) '^api/'>], [<URLPattern 'apple-app-site-association'>], [<URLPattern 'link_user'>]], 'path': 'logo.png'}

During handling of the above exception, another exception occurred:

Traceback (most recent call last):
  File "D:\virtualenv\bar\lib\site-packages\django\template\base.py", line 829, in _resolve_lookup
    current = current[bit]
TypeError: 'URLResolver' object is not subscriptable

During handling of the above exception, another exception occurred:

Traceback (most recent call last):
  File "D:\virtualenv\bar\lib\site-packages\django\template\base.py", line 837, in _resolve_lookup
    current = getattr(current, bit)
AttributeError: 'URLResolver' object has no attribute 'name'

During handling of the above exception, another exception occurred:

Traceback (most recent call last):
  File "D:\virtualenv\bar\lib\site-packages\django\template\base.py", line 843, in _resolve_lookup
    current = current[int(bit)]
ValueError: invalid literal for int() with base 10: 'name'

During handling of the above exception, another exception occurred:

Traceback (most recent call last):
  File "D:\virtualenv\bar\lib\site-packages\django\template\base.py", line 850, in _resolve_lookup
    (bit, current))  # missing attribute
django.template.base.VariableDoesNotExist: Failed lookup for key [name] in <URLResolver <URLPattern list> (admin:admin) 'admin/'>
Exception while resolving variable 'name' in template 'unknown'.
Traceback (most recent call last):
  File "D:\virtualenv\bar\lib\site-packages\django\core\handlers\exception.py", line 34, in inner
    response = get_response(request)
  File "D:\virtualenv\bar\lib\site-packages\django\core\handlers\base.py", line 111, in _get_response
    resolver_match = resolver.resolve(request.path_info)
  File "D:\virtualenv\bar\lib\site-packages\django\urls\resolvers.py", line 520, in resolve
    raise Resolver404({'tried': tried, 'path': new_path})
django.urls.exceptions.Resolver404: {'tried': [[<URLPattern '' [name='home']>], [<URLResolver <URLPattern list> (admin:admin) 'admin/'>], [<URLResolver <module 'bar.urls' from 'D:\\beam-dev\\beam-anywhere-relay\\bar\\urls.py'> (None:None) '^api/'>], [<URLPattern 'apple-app-site-association'>], [<URLPattern 'link_user'>]], 'path': 'logo.png'}

During handling of the above exception, another exception occurred:

Traceback (most recent call last):
  File "D:\virtualenv\bar\lib\site-packages\django\template\base.py", line 829, in _resolve_lookup
    current = current[bit]
TypeError: 'URLResolver' object is not subscriptable

During handling of the above exception, another exception occurred:

Traceback (most recent call last):
  File "D:\virtualenv\bar\lib\site-packages\django\template\base.py", line 837, in _resolve_lookup
    current = getattr(current, bit)
AttributeError: 'URLResolver' object has no attribute 'name'

During handling of the above exception, another exception occurred:

Traceback (most recent call last):
  File "D:\virtualenv\bar\lib\site-packages\django\template\base.py", line 843, in _resolve_lookup
    current = current[int(bit)]
ValueError: invalid literal for int() with base 10: 'name'

During handling of the above exception, another exception occurred:

Traceback (most recent call last):
  File "D:\virtualenv\bar\lib\site-packages\django\template\base.py", line 850, in _resolve_lookup
    (bit, current))  # missing attribute
django.template.base.VariableDoesNotExist: Failed lookup for key [name] in <URLResolver <module 'bar.urls' from 'D:\\beam-dev\\beam-anywhere-relay\\bar\\urls.py'> (None:None) '^api/'>
Not Found: /logo.png
"GET /logo.png HTTP/1.1" 404 2429
"GET / HTTP/1.1" 200 935
Exception while resolving variable 'name' in template 'unknown'.
Traceback (most recent call last):
  File "D:\virtualenv\bar\lib\site-packages\django\core\handlers\exception.py", line 34, in inner
    response = get_response(request)
  File "D:\virtualenv\bar\lib\site-packages\django\core\handlers\base.py", line 111, in _get_response
    resolver_match = resolver.resolve(request.path_info)
  File "D:\virtualenv\bar\lib\site-packages\django\urls\resolvers.py", line 520, in resolve
    raise Resolver404({'tried': tried, 'path': new_path})
django.urls.exceptions.Resolver404: {'tried': [[<URLPattern '' [name='home']>], [<URLResolver <URLPattern list> (admin:admin) 'admin/'>], [<URLResolver <module 'bar.urls' from 'D:\\beam-dev\\beam-anywhere-relay\\bar\\urls.py'> (None:None) '^api/'>], [<URLPattern 'apple-app-site-association'>], [<URLPattern 'link_user'>]], 'path': 'logo.png'}

During handling of the above exception, another exception occurred:

Traceback (most recent call last):
  File "D:\virtualenv\bar\lib\site-packages\django\template\base.py", line 829, in _resolve_lookup
    current = current[bit]
TypeError: 'URLResolver' object is not subscriptable

During handling of the above exception, another exception occurred:

Traceback (most recent call last):
  File "D:\virtualenv\bar\lib\site-packages\django\template\base.py", line 837, in _resolve_lookup
    current = getattr(current, bit)
AttributeError: 'URLResolver' object has no attribute 'name'

During handling of the above exception, another exception occurred:

Traceback (most recent call last):
  File "D:\virtualenv\bar\lib\site-packages\django\template\base.py", line 843, in _resolve_lookup
    current = current[int(bit)]
ValueError: invalid literal for int() with base 10: 'name'

During handling of the above exception, another exception occurred:

Traceback (most recent call last):
  File "D:\virtualenv\bar\lib\site-packages\django\template\base.py", line 850, in _resolve_lookup
    (bit, current))  # missing attribute
django.template.base.VariableDoesNotExist: Failed lookup for key [name] in <URLResolver <URLPattern list> (admin:admin) 'admin/'>
Exception while resolving variable 'name' in template 'unknown'.
Traceback (most recent call last):
  File "D:\virtualenv\bar\lib\site-packages\django\core\handlers\exception.py", line 34, in inner
    response = get_response(request)
  File "D:\virtualenv\bar\lib\site-packages\django\core\handlers\base.py", line 111, in _get_response
    resolver_match = resolver.resolve(request.path_info)
  File "D:\virtualenv\bar\lib\site-packages\django\urls\resolvers.py", line 520, in resolve
    raise Resolver404({'tried': tried, 'path': new_path})
django.urls.exceptions.Resolver404: {'tried': [[<URLPattern '' [name='home']>], [<URLResolver <URLPattern list> (admin:admin) 'admin/'>], [<URLResolver <module 'bar.urls' from 'D:\\beam-dev\\beam-anywhere-relay\\bar\\urls.py'> (None:None) '^api/'>], [<URLPattern 'apple-app-site-association'>], [<URLPattern 'link_user'>]], 'path': 'logo.png'}

During handling of the above exception, another exception occurred:

Traceback (most recent call last):
  File "D:\virtualenv\bar\lib\site-packages\django\template\base.py", line 829, in _resolve_lookup
    current = current[bit]
TypeError: 'URLResolver' object is not subscriptable

During handling of the above exception, another exception occurred:

Traceback (most recent call last):
  File "D:\virtualenv\bar\lib\site-packages\django\template\base.py", line 837, in _resolve_lookup
    current = getattr(current, bit)
AttributeError: 'URLResolver' object has no attribute 'name'

During handling of the above exception, another exception occurred:

Traceback (most recent call last):
  File "D:\virtualenv\bar\lib\site-packages\django\template\base.py", line 843, in _resolve_lookup
    current = current[int(bit)]
ValueError: invalid literal for int() with base 10: 'name'

During handling of the above exception, another exception occurred:

Traceback (most recent call last):
  File "D:\virtualenv\bar\lib\site-packages\django\template\base.py", line 850, in _resolve_lookup
    (bit, current))  # missing attribute
django.template.base.VariableDoesNotExist: Failed lookup for key [name] in <URLResolver <module 'bar.urls' from 'D:\\beam-dev\\beam-anywhere-relay\\bar\\urls.py'> (None:None) '^api/'>
Not Found: /logo.png
"GET /logo.png HTTP/1.1" 404 2429
"GET / HTTP/1.1" 200 935
Exception while resolving variable 'name' in template 'unknown'.
Traceback (most recent call last):
  File "D:\virtualenv\bar\lib\site-packages\django\core\handlers\exception.py", line 34, in inner
    response = get_response(request)
  File "D:\virtualenv\bar\lib\site-packages\django\core\handlers\base.py", line 111, in _get_response
    resolver_match = resolver.resolve(request.path_info)
  File "D:\virtualenv\bar\lib\site-packages\django\urls\resolvers.py", line 520, in resolve
    raise Resolver404({'tried': tried, 'path': new_path})
django.urls.exceptions.Resolver404: {'tried': [[<URLPattern '' [name='home']>], [<URLResolver <URLPattern list> (admin:admin) 'admin/'>], [<URLResolver <module 'bar.urls' from 'D:\\beam-dev\\beam-anywhere-relay\\bar\\urls.py'> (None:None) '^api/'>], [<URLPattern 'apple-app-site-association'>], [<URLPattern 'link_user'>]], 'path': 'logo.png'}

During handling of the above exception, another exception occurred:

Traceback (most recent call last):
  File "D:\virtualenv\bar\lib\site-packages\django\template\base.py", line 829, in _resolve_lookup
    current = current[bit]
TypeError: 'URLResolver' object is not subscriptable

During handling of the above exception, another exception occurred:

Traceback (most recent call last):
  File "D:\virtualenv\bar\lib\site-packages\django\template\base.py", line 837, in _resolve_lookup
    current = getattr(current, bit)
AttributeError: 'URLResolver' object has no attribute 'name'

During handling of the above exception, another exception occurred:

Traceback (most recent call last):
  File "D:\virtualenv\bar\lib\site-packages\django\template\base.py", line 843, in _resolve_lookup
    current = current[int(bit)]
ValueError: invalid literal for int() with base 10: 'name'

During handling of the above exception, another exception occurred:

Traceback (most recent call last):
  File "D:\virtualenv\bar\lib\site-packages\django\template\base.py", line 850, in _resolve_lookup
    (bit, current))  # missing attribute
django.template.base.VariableDoesNotExist: Failed lookup for key [name] in <URLResolver <URLPattern list> (admin:admin) 'admin/'>
Exception while resolving variable 'name' in template 'unknown'.
Traceback (most recent call last):
  File "D:\virtualenv\bar\lib\site-packages\django\core\handlers\exception.py", line 34, in inner
    response = get_response(request)
  File "D:\virtualenv\bar\lib\site-packages\django\core\handlers\base.py", line 111, in _get_response
    resolver_match = resolver.resolve(request.path_info)
  File "D:\virtualenv\bar\lib\site-packages\django\urls\resolvers.py", line 520, in resolve
    raise Resolver404({'tried': tried, 'path': new_path})
django.urls.exceptions.Resolver404: {'tried': [[<URLPattern '' [name='home']>], [<URLResolver <URLPattern list> (admin:admin) 'admin/'>], [<URLResolver <module 'bar.urls' from 'D:\\beam-dev\\beam-anywhere-relay\\bar\\urls.py'> (None:None) '^api/'>], [<URLPattern 'apple-app-site-association'>], [<URLPattern 'link_user'>]], 'path': 'logo.png'}

During handling of the above exception, another exception occurred:

Traceback (most recent call last):
  File "D:\virtualenv\bar\lib\site-packages\django\template\base.py", line 829, in _resolve_lookup
    current = current[bit]
TypeError: 'URLResolver' object is not subscriptable

During handling of the above exception, another exception occurred:

Traceback (most recent call last):
  File "D:\virtualenv\bar\lib\site-packages\django\template\base.py", line 837, in _resolve_lookup
    current = getattr(current, bit)
AttributeError: 'URLResolver' object has no attribute 'name'

During handling of the above exception, another exception occurred:

Traceback (most recent call last):
  File "D:\virtualenv\bar\lib\site-packages\django\template\base.py", line 843, in _resolve_lookup
    current = current[int(bit)]
ValueError: invalid literal for int() with base 10: 'name'

During handling of the above exception, another exception occurred:

Traceback (most recent call last):
  File "D:\virtualenv\bar\lib\site-packages\django\template\base.py", line 850, in _resolve_lookup
    (bit, current))  # missing attribute
django.template.base.VariableDoesNotExist: Failed lookup for key [name] in <URLResolver <module 'bar.urls' from 'D:\\beam-dev\\beam-anywhere-relay\\bar\\urls.py'> (None:None) '^api/'>
Not Found: /logo.png
"GET /logo.png HTTP/1.1" 404 2429
"GET / HTTP/1.1" 200 935
Exception while resolving variable 'name' in template 'unknown'.
Traceback (most recent call last):
  File "D:\virtualenv\bar\lib\site-packages\django\core\handlers\exception.py", line 34, in inner
    response = get_response(request)
  File "D:\virtualenv\bar\lib\site-packages\django\core\handlers\base.py", line 111, in _get_response
    resolver_match = resolver.resolve(request.path_info)
  File "D:\virtualenv\bar\lib\site-packages\django\urls\resolvers.py", line 520, in resolve
    raise Resolver404({'tried': tried, 'path': new_path})
django.urls.exceptions.Resolver404: {'tried': [[<URLPattern '' [name='home']>], [<URLResolver <URLPattern list> (admin:admin) 'admin/'>], [<URLResolver <module 'bar.urls' from 'D:\\beam-dev\\beam-anywhere-relay\\bar\\urls.py'> (None:None) '^api/'>], [<URLPattern 'apple-app-site-association'>], [<URLPattern 'link_user'>]], 'path': 'logo.png'}

During handling of the above exception, another exception occurred:

Traceback (most recent call last):
  File "D:\virtualenv\bar\lib\site-packages\django\template\base.py", line 829, in _resolve_lookup
    current = current[bit]
TypeError: 'URLResolver' object is not subscriptable

During handling of the above exception, another exception occurred:

Traceback (most recent call last):
  File "D:\virtualenv\bar\lib\site-packages\django\template\base.py", line 837, in _resolve_lookup
    current = getattr(current, bit)
AttributeError: 'URLResolver' object has no attribute 'name'

During handling of the above exception, another exception occurred:

Traceback (most recent call last):
  File "D:\virtualenv\bar\lib\site-packages\django\template\base.py", line 843, in _resolve_lookup
    current = current[int(bit)]
ValueError: invalid literal for int() with base 10: 'name'

During handling of the above exception, another exception occurred:

Traceback (most recent call last):
  File "D:\virtualenv\bar\lib\site-packages\django\template\base.py", line 850, in _resolve_lookup
    (bit, current))  # missing attribute
django.template.base.VariableDoesNotExist: Failed lookup for key [name] in <URLResolver <URLPattern list> (admin:admin) 'admin/'>
Exception while resolving variable 'name' in template 'unknown'.
Traceback (most recent call last):
  File "D:\virtualenv\bar\lib\site-packages\django\core\handlers\exception.py", line 34, in inner
    response = get_response(request)
  File "D:\virtualenv\bar\lib\site-packages\django\core\handlers\base.py", line 111, in _get_response
    resolver_match = resolver.resolve(request.path_info)
  File "D:\virtualenv\bar\lib\site-packages\django\urls\resolvers.py", line 520, in resolve
    raise Resolver404({'tried': tried, 'path': new_path})
django.urls.exceptions.Resolver404: {'tried': [[<URLPattern '' [name='home']>], [<URLResolver <URLPattern list> (admin:admin) 'admin/'>], [<URLResolver <module 'bar.urls' from 'D:\\beam-dev\\beam-anywhere-relay\\bar\\urls.py'> (None:None) '^api/'>], [<URLPattern 'apple-app-site-association'>], [<URLPattern 'link_user'>]], 'path': 'logo.png'}

During handling of the above exception, another exception occurred:

Traceback (most recent call last):
  File "D:\virtualenv\bar\lib\site-packages\django\template\base.py", line 829, in _resolve_lookup
    current = current[bit]
TypeError: 'URLResolver' object is not subscriptable

During handling of the above exception, another exception occurred:

Traceback (most recent call last):
  File "D:\virtualenv\bar\lib\site-packages\django\template\base.py", line 837, in _resolve_lookup
    current = getattr(current, bit)
AttributeError: 'URLResolver' object has no attribute 'name'

During handling of the above exception, another exception occurred:

Traceback (most recent call last):
  File "D:\virtualenv\bar\lib\site-packages\django\template\base.py", line 843, in _resolve_lookup
    current = current[int(bit)]
ValueError: invalid literal for int() with base 10: 'name'

During handling of the above exception, another exception occurred:

Traceback (most recent call last):
  File "D:\virtualenv\bar\lib\site-packages\django\template\base.py", line 850, in _resolve_lookup
    (bit, current))  # missing attribute
django.template.base.VariableDoesNotExist: Failed lookup for key [name] in <URLResolver <module 'bar.urls' from 'D:\\beam-dev\\beam-anywhere-relay\\bar\\urls.py'> (None:None) '^api/'>
Not Found: /logo.png
"GET /logo.png HTTP/1.1" 404 2429
"GET / HTTP/1.1" 200 487
Exception while resolving variable 'name' in template 'unknown'.
Traceback (most recent call last):
  File "D:\virtualenv\bar\lib\site-packages\django\core\handlers\exception.py", line 34, in inner
    response = get_response(request)
  File "D:\virtualenv\bar\lib\site-packages\django\core\handlers\base.py", line 111, in _get_response
    resolver_match = resolver.resolve(request.path_info)
  File "D:\virtualenv\bar\lib\site-packages\django\urls\resolvers.py", line 520, in resolve
    raise Resolver404({'tried': tried, 'path': new_path})
django.urls.exceptions.Resolver404: {'tried': [[<URLPattern '' [name='home']>], [<URLResolver <URLPattern list> (admin:admin) 'admin/'>], [<URLResolver <module 'bar.urls' from 'D:\\beam-dev\\beam-anywhere-relay\\bar\\urls.py'> (None:None) '^api/'>], [<URLPattern 'apple-app-site-association'>], [<URLPattern 'link_user'>]], 'path': 'logo.png'}

During handling of the above exception, another exception occurred:

Traceback (most recent call last):
  File "D:\virtualenv\bar\lib\site-packages\django\template\base.py", line 829, in _resolve_lookup
    current = current[bit]
TypeError: 'URLResolver' object is not subscriptable

During handling of the above exception, another exception occurred:

Traceback (most recent call last):
  File "D:\virtualenv\bar\lib\site-packages\django\template\base.py", line 837, in _resolve_lookup
    current = getattr(current, bit)
AttributeError: 'URLResolver' object has no attribute 'name'

During handling of the above exception, another exception occurred:

Traceback (most recent call last):
  File "D:\virtualenv\bar\lib\site-packages\django\template\base.py", line 843, in _resolve_lookup
    current = current[int(bit)]
ValueError: invalid literal for int() with base 10: 'name'

During handling of the above exception, another exception occurred:

Traceback (most recent call last):
  File "D:\virtualenv\bar\lib\site-packages\django\template\base.py", line 850, in _resolve_lookup
    (bit, current))  # missing attribute
django.template.base.VariableDoesNotExist: Failed lookup for key [name] in <URLResolver <URLPattern list> (admin:admin) 'admin/'>
Exception while resolving variable 'name' in template 'unknown'.
Traceback (most recent call last):
  File "D:\virtualenv\bar\lib\site-packages\django\core\handlers\exception.py", line 34, in inner
    response = get_response(request)
  File "D:\virtualenv\bar\lib\site-packages\django\core\handlers\base.py", line 111, in _get_response
    resolver_match = resolver.resolve(request.path_info)
  File "D:\virtualenv\bar\lib\site-packages\django\urls\resolvers.py", line 520, in resolve
    raise Resolver404({'tried': tried, 'path': new_path})
django.urls.exceptions.Resolver404: {'tried': [[<URLPattern '' [name='home']>], [<URLResolver <URLPattern list> (admin:admin) 'admin/'>], [<URLResolver <module 'bar.urls' from 'D:\\beam-dev\\beam-anywhere-relay\\bar\\urls.py'> (None:None) '^api/'>], [<URLPattern 'apple-app-site-association'>], [<URLPattern 'link_user'>]], 'path': 'logo.png'}

During handling of the above exception, another exception occurred:

Traceback (most recent call last):
  File "D:\virtualenv\bar\lib\site-packages\django\template\base.py", line 829, in _resolve_lookup
    current = current[bit]
TypeError: 'URLResolver' object is not subscriptable

During handling of the above exception, another exception occurred:

Traceback (most recent call last):
  File "D:\virtualenv\bar\lib\site-packages\django\template\base.py", line 837, in _resolve_lookup
    current = getattr(current, bit)
AttributeError: 'URLResolver' object has no attribute 'name'

During handling of the above exception, another exception occurred:

Traceback (most recent call last):
  File "D:\virtualenv\bar\lib\site-packages\django\template\base.py", line 843, in _resolve_lookup
    current = current[int(bit)]
ValueError: invalid literal for int() with base 10: 'name'

During handling of the above exception, another exception occurred:

Traceback (most recent call last):
  File "D:\virtualenv\bar\lib\site-packages\django\template\base.py", line 850, in _resolve_lookup
    (bit, current))  # missing attribute
django.template.base.VariableDoesNotExist: Failed lookup for key [name] in <URLResolver <module 'bar.urls' from 'D:\\beam-dev\\beam-anywhere-relay\\bar\\urls.py'> (None:None) '^api/'>
Not Found: /logo.png
"GET /logo.png HTTP/1.1" 404 2429
"GET / HTTP/1.1" 200 487
Exception while resolving variable 'name' in template 'unknown'.
Traceback (most recent call last):
  File "D:\virtualenv\bar\lib\site-packages\django\core\handlers\exception.py", line 34, in inner
    response = get_response(request)
  File "D:\virtualenv\bar\lib\site-packages\django\core\handlers\base.py", line 111, in _get_response
    resolver_match = resolver.resolve(request.path_info)
  File "D:\virtualenv\bar\lib\site-packages\django\urls\resolvers.py", line 520, in resolve
    raise Resolver404({'tried': tried, 'path': new_path})
django.urls.exceptions.Resolver404: {'tried': [[<URLPattern '' [name='home']>], [<URLResolver <URLPattern list> (admin:admin) 'admin/'>], [<URLResolver <module 'bar.urls' from 'D:\\beam-dev\\beam-anywhere-relay\\bar\\urls.py'> (None:None) '^api/'>], [<URLPattern 'apple-app-site-association'>], [<URLPattern 'link_user'>]], 'path': 'logo.png'}

During handling of the above exception, another exception occurred:

Traceback (most recent call last):
  File "D:\virtualenv\bar\lib\site-packages\django\template\base.py", line 829, in _resolve_lookup
    current = current[bit]
TypeError: 'URLResolver' object is not subscriptable

During handling of the above exception, another exception occurred:

Traceback (most recent call last):
  File "D:\virtualenv\bar\lib\site-packages\django\template\base.py", line 837, in _resolve_lookup
    current = getattr(current, bit)
AttributeError: 'URLResolver' object has no attribute 'name'

During handling of the above exception, another exception occurred:

Traceback (most recent call last):
  File "D:\virtualenv\bar\lib\site-packages\django\template\base.py", line 843, in _resolve_lookup
    current = current[int(bit)]
ValueError: invalid literal for int() with base 10: 'name'

During handling of the above exception, another exception occurred:

Traceback (most recent call last):
  File "D:\virtualenv\bar\lib\site-packages\django\template\base.py", line 850, in _resolve_lookup
    (bit, current))  # missing attribute
django.template.base.VariableDoesNotExist: Failed lookup for key [name] in <URLResolver <URLPattern list> (admin:admin) 'admin/'>
Exception while resolving variable 'name' in template 'unknown'.
Traceback (most recent call last):
  File "D:\virtualenv\bar\lib\site-packages\django\core\handlers\exception.py", line 34, in inner
    response = get_response(request)
  File "D:\virtualenv\bar\lib\site-packages\django\core\handlers\base.py", line 111, in _get_response
    resolver_match = resolver.resolve(request.path_info)
  File "D:\virtualenv\bar\lib\site-packages\django\urls\resolvers.py", line 520, in resolve
    raise Resolver404({'tried': tried, 'path': new_path})
django.urls.exceptions.Resolver404: {'tried': [[<URLPattern '' [name='home']>], [<URLResolver <URLPattern list> (admin:admin) 'admin/'>], [<URLResolver <module 'bar.urls' from 'D:\\beam-dev\\beam-anywhere-relay\\bar\\urls.py'> (None:None) '^api/'>], [<URLPattern 'apple-app-site-association'>], [<URLPattern 'link_user'>]], 'path': 'logo.png'}

During handling of the above exception, another exception occurred:

Traceback (most recent call last):
  File "D:\virtualenv\bar\lib\site-packages\django\template\base.py", line 829, in _resolve_lookup
    current = current[bit]
TypeError: 'URLResolver' object is not subscriptable

During handling of the above exception, another exception occurred:

Traceback (most recent call last):
  File "D:\virtualenv\bar\lib\site-packages\django\template\base.py", line 837, in _resolve_lookup
    current = getattr(current, bit)
AttributeError: 'URLResolver' object has no attribute 'name'

During handling of the above exception, another exception occurred:

Traceback (most recent call last):
  File "D:\virtualenv\bar\lib\site-packages\django\template\base.py", line 843, in _resolve_lookup
    current = current[int(bit)]
ValueError: invalid literal for int() with base 10: 'name'

During handling of the above exception, another exception occurred:

Traceback (most recent call last):
  File "D:\virtualenv\bar\lib\site-packages\django\template\base.py", line 850, in _resolve_lookup
    (bit, current))  # missing attribute
django.template.base.VariableDoesNotExist: Failed lookup for key [name] in <URLResolver <module 'bar.urls' from 'D:\\beam-dev\\beam-anywhere-relay\\bar\\urls.py'> (None:None) '^api/'>
Not Found: /logo.png
"GET /logo.png HTTP/1.1" 404 2429
"GET / HTTP/1.1" 200 487
Exception while resolving variable 'name' in template 'unknown'.
Traceback (most recent call last):
  File "D:\virtualenv\bar\lib\site-packages\django\core\handlers\exception.py", line 34, in inner
    response = get_response(request)
  File "D:\virtualenv\bar\lib\site-packages\django\core\handlers\base.py", line 111, in _get_response
    resolver_match = resolver.resolve(request.path_info)
  File "D:\virtualenv\bar\lib\site-packages\django\urls\resolvers.py", line 520, in resolve
    raise Resolver404({'tried': tried, 'path': new_path})
django.urls.exceptions.Resolver404: {'tried': [[<URLPattern '' [name='home']>], [<URLResolver <URLPattern list> (admin:admin) 'admin/'>], [<URLResolver <module 'bar.urls' from 'D:\\beam-dev\\beam-anywhere-relay\\bar\\urls.py'> (None:None) '^api/'>], [<URLPattern 'apple-app-site-association'>], [<URLPattern 'link_user'>]], 'path': 'logo.png'}

During handling of the above exception, another exception occurred:

Traceback (most recent call last):
  File "D:\virtualenv\bar\lib\site-packages\django\template\base.py", line 829, in _resolve_lookup
    current = current[bit]
TypeError: 'URLResolver' object is not subscriptable

During handling of the above exception, another exception occurred:

Traceback (most recent call last):
  File "D:\virtualenv\bar\lib\site-packages\django\template\base.py", line 837, in _resolve_lookup
    current = getattr(current, bit)
AttributeError: 'URLResolver' object has no attribute 'name'

During handling of the above exception, another exception occurred:

Traceback (most recent call last):
  File "D:\virtualenv\bar\lib\site-packages\django\template\base.py", line 843, in _resolve_lookup
    current = current[int(bit)]
ValueError: invalid literal for int() with base 10: 'name'

During handling of the above exception, another exception occurred:

Traceback (most recent call last):
  File "D:\virtualenv\bar\lib\site-packages\django\template\base.py", line 850, in _resolve_lookup
    (bit, current))  # missing attribute
django.template.base.VariableDoesNotExist: Failed lookup for key [name] in <URLResolver <URLPattern list> (admin:admin) 'admin/'>
Exception while resolving variable 'name' in template 'unknown'.
Traceback (most recent call last):
  File "D:\virtualenv\bar\lib\site-packages\django\core\handlers\exception.py", line 34, in inner
    response = get_response(request)
  File "D:\virtualenv\bar\lib\site-packages\django\core\handlers\base.py", line 111, in _get_response
    resolver_match = resolver.resolve(request.path_info)
  File "D:\virtualenv\bar\lib\site-packages\django\urls\resolvers.py", line 520, in resolve
    raise Resolver404({'tried': tried, 'path': new_path})
django.urls.exceptions.Resolver404: {'tried': [[<URLPattern '' [name='home']>], [<URLResolver <URLPattern list> (admin:admin) 'admin/'>], [<URLResolver <module 'bar.urls' from 'D:\\beam-dev\\beam-anywhere-relay\\bar\\urls.py'> (None:None) '^api/'>], [<URLPattern 'apple-app-site-association'>], [<URLPattern 'link_user'>]], 'path': 'logo.png'}

During handling of the above exception, another exception occurred:

Traceback (most recent call last):
  File "D:\virtualenv\bar\lib\site-packages\django\template\base.py", line 829, in _resolve_lookup
    current = current[bit]
TypeError: 'URLResolver' object is not subscriptable

During handling of the above exception, another exception occurred:

Traceback (most recent call last):
  File "D:\virtualenv\bar\lib\site-packages\django\template\base.py", line 837, in _resolve_lookup
    current = getattr(current, bit)
AttributeError: 'URLResolver' object has no attribute 'name'

During handling of the above exception, another exception occurred:

Traceback (most recent call last):
  File "D:\virtualenv\bar\lib\site-packages\django\template\base.py", line 843, in _resolve_lookup
    current = current[int(bit)]
ValueError: invalid literal for int() with base 10: 'name'

During handling of the above exception, another exception occurred:

Traceback (most recent call last):
  File "D:\virtualenv\bar\lib\site-packages\django\template\base.py", line 850, in _resolve_lookup
    (bit, current))  # missing attribute
django.template.base.VariableDoesNotExist: Failed lookup for key [name] in <URLResolver <module 'bar.urls' from 'D:\\beam-dev\\beam-anywhere-relay\\bar\\urls.py'> (None:None) '^api/'>
Not Found: /logo.png
"GET /logo.png HTTP/1.1" 404 2429
"GET / HTTP/1.1" 200 935
Exception while resolving variable 'name' in template 'unknown'.
Traceback (most recent call last):
  File "D:\virtualenv\bar\lib\site-packages\django\core\handlers\exception.py", line 34, in inner
    response = get_response(request)
  File "D:\virtualenv\bar\lib\site-packages\django\core\handlers\base.py", line 111, in _get_response
    resolver_match = resolver.resolve(request.path_info)
  File "D:\virtualenv\bar\lib\site-packages\django\urls\resolvers.py", line 520, in resolve
    raise Resolver404({'tried': tried, 'path': new_path})
django.urls.exceptions.Resolver404: {'tried': [[<URLPattern '' [name='home']>], [<URLResolver <URLPattern list> (admin:admin) 'admin/'>], [<URLResolver <module 'bar.urls' from 'D:\\beam-dev\\beam-anywhere-relay\\bar\\urls.py'> (None:None) '^api/'>], [<URLPattern 'apple-app-site-association'>], [<URLPattern 'link_user'>]], 'path': 'logo.png'}

During handling of the above exception, another exception occurred:

Traceback (most recent call last):
  File "D:\virtualenv\bar\lib\site-packages\django\template\base.py", line 829, in _resolve_lookup
    current = current[bit]
TypeError: 'URLResolver' object is not subscriptable

During handling of the above exception, another exception occurred:

Traceback (most recent call last):
  File "D:\virtualenv\bar\lib\site-packages\django\template\base.py", line 837, in _resolve_lookup
    current = getattr(current, bit)
AttributeError: 'URLResolver' object has no attribute 'name'

During handling of the above exception, another exception occurred:

Traceback (most recent call last):
  File "D:\virtualenv\bar\lib\site-packages\django\template\base.py", line 843, in _resolve_lookup
    current = current[int(bit)]
ValueError: invalid literal for int() with base 10: 'name'

During handling of the above exception, another exception occurred:

Traceback (most recent call last):
  File "D:\virtualenv\bar\lib\site-packages\django\template\base.py", line 850, in _resolve_lookup
    (bit, current))  # missing attribute
django.template.base.VariableDoesNotExist: Failed lookup for key [name] in <URLResolver <URLPattern list> (admin:admin) 'admin/'>
Exception while resolving variable 'name' in template 'unknown'.
Traceback (most recent call last):
  File "D:\virtualenv\bar\lib\site-packages\django\core\handlers\exception.py", line 34, in inner
    response = get_response(request)
  File "D:\virtualenv\bar\lib\site-packages\django\core\handlers\base.py", line 111, in _get_response
    resolver_match = resolver.resolve(request.path_info)
  File "D:\virtualenv\bar\lib\site-packages\django\urls\resolvers.py", line 520, in resolve
    raise Resolver404({'tried': tried, 'path': new_path})
django.urls.exceptions.Resolver404: {'tried': [[<URLPattern '' [name='home']>], [<URLResolver <URLPattern list> (admin:admin) 'admin/'>], [<URLResolver <module 'bar.urls' from 'D:\\beam-dev\\beam-anywhere-relay\\bar\\urls.py'> (None:None) '^api/'>], [<URLPattern 'apple-app-site-association'>], [<URLPattern 'link_user'>]], 'path': 'logo.png'}

During handling of the above exception, another exception occurred:

Traceback (most recent call last):
  File "D:\virtualenv\bar\lib\site-packages\django\template\base.py", line 829, in _resolve_lookup
    current = current[bit]
TypeError: 'URLResolver' object is not subscriptable

During handling of the above exception, another exception occurred:

Traceback (most recent call last):
  File "D:\virtualenv\bar\lib\site-packages\django\template\base.py", line 837, in _resolve_lookup
    current = getattr(current, bit)
AttributeError: 'URLResolver' object has no attribute 'name'

During handling of the above exception, another exception occurred:

Traceback (most recent call last):
  File "D:\virtualenv\bar\lib\site-packages\django\template\base.py", line 843, in _resolve_lookup
    current = current[int(bit)]
ValueError: invalid literal for int() with base 10: 'name'

During handling of the above exception, another exception occurred:

Traceback (most recent call last):
  File "D:\virtualenv\bar\lib\site-packages\django\template\base.py", line 850, in _resolve_lookup
    (bit, current))  # missing attribute
django.template.base.VariableDoesNotExist: Failed lookup for key [name] in <URLResolver <module 'bar.urls' from 'D:\\beam-dev\\beam-anywhere-relay\\bar\\urls.py'> (None:None) '^api/'>
Not Found: /logo.png
"GET /logo.png HTTP/1.1" 404 2429
(0.000) BEGIN; args=None
(0.001) INSERT INTO "bar_notification" ("transaction_status", "push_status", "send_from", "amount", "fee", "created_at", "updated_at", "push_type") VALUES ('initiated', 1, '/topics/1444f91b01c88d030e846ce505b382d0d088f0f50f98f69d45958e0e6dca5', 1, 1.0, '2019-05-06 14:55:44.330800', '2019-05-06 14:55:44.330800', 0); args=['initiated', 1, '/topics/1444f91b01c88d030e846ce505b382d0d088f0f50f98f69d45958e0e6dca5', 1, 1.0, '2019-05-06 14:55:44.330800', '2019-05-06 14:55:44.330800', 0]
Internal Server Error: /api/send_notification
Traceback (most recent call last):
  File "D:\virtualenv\bar\lib\site-packages\django\core\handlers\exception.py", line 34, in inner
    response = get_response(request)
  File "D:\virtualenv\bar\lib\site-packages\django\core\handlers\base.py", line 126, in _get_response
    response = self.process_exception_by_middleware(e, request)
  File "D:\virtualenv\bar\lib\site-packages\django\core\handlers\base.py", line 124, in _get_response
    response = wrapped_callback(request, *callback_args, **callback_kwargs)
  File "D:\virtualenv\bar\lib\site-packages\django\views\decorators\csrf.py", line 54, in wrapped_view
    return view_func(*args, **kwargs)
  File "D:\virtualenv\bar\lib\site-packages\django\views\generic\base.py", line 68, in view
    return self.dispatch(request, *args, **kwargs)
  File "D:\virtualenv\bar\lib\site-packages\rest_framework\views.py", line 495, in dispatch
    response = self.handle_exception(exc)
  File "D:\virtualenv\bar\lib\site-packages\rest_framework\views.py", line 455, in handle_exception
    self.raise_uncaught_exception(exc)
  File "D:\virtualenv\bar\lib\site-packages\rest_framework\views.py", line 492, in dispatch
    response = handler(request, *args, **kwargs)
  File "D:\beam-dev\beam-anywhere-relay\bar\views.py", line 171, in post
    'Authorization': 'key=' + API_KEY,
TypeError: must be str, not dict
"POST /api/send_notification HTTP/1.1" 500 20187
(0.000) SELECT "bar_user"."id", "bar_user"."username", "bar_user"."user_id", "bar_user"."push_token", "bar_user"."wallet_address", "bar_user"."created_at", "bar_user"."msgr_type" FROM "bar_user" WHERE ("bar_user"."msgr_type" = 'tg' AND "bar_user"."user_id" = 123); args=('tg', 123)
(0.000) BEGIN; args=None
(0.000) INSERT INTO "bar_notification" ("transaction_status", "push_status", "send_from", "amount", "fee", "created_at", "updated_at", "push_type") VALUES ('initiated', 1, '123', 1, 1.0, '2019-05-06 14:56:04.548720', '2019-05-06 14:56:04.548720', 0); args=['initiated', 1, '123', 1, 1.0, '2019-05-06 14:56:04.548720', '2019-05-06 14:56:04.548720', 0]
Internal Server Error: /api/send_notification
Traceback (most recent call last):
  File "D:\virtualenv\bar\lib\site-packages\django\core\handlers\exception.py", line 34, in inner
    response = get_response(request)
  File "D:\virtualenv\bar\lib\site-packages\django\core\handlers\base.py", line 126, in _get_response
    response = self.process_exception_by_middleware(e, request)
  File "D:\virtualenv\bar\lib\site-packages\django\core\handlers\base.py", line 124, in _get_response
    response = wrapped_callback(request, *callback_args, **callback_kwargs)
  File "D:\virtualenv\bar\lib\site-packages\django\views\decorators\csrf.py", line 54, in wrapped_view
    return view_func(*args, **kwargs)
  File "D:\virtualenv\bar\lib\site-packages\django\views\generic\base.py", line 68, in view
    return self.dispatch(request, *args, **kwargs)
  File "D:\virtualenv\bar\lib\site-packages\rest_framework\views.py", line 495, in dispatch
    response = self.handle_exception(exc)
  File "D:\virtualenv\bar\lib\site-packages\rest_framework\views.py", line 455, in handle_exception
    self.raise_uncaught_exception(exc)
  File "D:\virtualenv\bar\lib\site-packages\rest_framework\views.py", line 492, in dispatch
    response = handler(request, *args, **kwargs)
  File "D:\beam-dev\beam-anywhere-relay\bar\views.py", line 171, in post
    'Authorization': 'key=' + API_KEY,
TypeError: must be str, not dict
"POST /api/send_notification HTTP/1.1" 500 20187
(0.000) SELECT "bar_user"."id", "bar_user"."username", "bar_user"."user_id", "bar_user"."push_token", "bar_user"."wallet_address", "bar_user"."created_at", "bar_user"."msgr_type" FROM "bar_user" WHERE ("bar_user"."msgr_type" = 'tg' AND "bar_user"."user_id" = 123); args=('tg', 123)
(0.000) BEGIN; args=None
(0.001) INSERT INTO "bar_notification" ("transaction_status", "push_status", "send_from", "amount", "fee", "created_at", "updated_at", "push_type") VALUES ('initiated', 1, '123', 1, 1.0, '2019-05-06 14:58:50.748561', '2019-05-06 14:58:50.748561', 0); args=['initiated', 1, '123', 1, 1.0, '2019-05-06 14:58:50.748561', '2019-05-06 14:58:50.748561', 0]
Internal Server Error: /api/send_notification
Traceback (most recent call last):
  File "D:\virtualenv\bar\lib\site-packages\django\core\handlers\exception.py", line 34, in inner
    response = get_response(request)
  File "D:\virtualenv\bar\lib\site-packages\django\core\handlers\base.py", line 126, in _get_response
    response = self.process_exception_by_middleware(e, request)
  File "D:\virtualenv\bar\lib\site-packages\django\core\handlers\base.py", line 124, in _get_response
    response = wrapped_callback(request, *callback_args, **callback_kwargs)
  File "D:\virtualenv\bar\lib\site-packages\django\views\decorators\csrf.py", line 54, in wrapped_view
    return view_func(*args, **kwargs)
  File "D:\virtualenv\bar\lib\site-packages\django\views\generic\base.py", line 68, in view
    return self.dispatch(request, *args, **kwargs)
  File "D:\virtualenv\bar\lib\site-packages\rest_framework\views.py", line 495, in dispatch
    response = self.handle_exception(exc)
  File "D:\virtualenv\bar\lib\site-packages\rest_framework\views.py", line 455, in handle_exception
    self.raise_uncaught_exception(exc)
  File "D:\virtualenv\bar\lib\site-packages\rest_framework\views.py", line 492, in dispatch
    response = handler(request, *args, **kwargs)
  File "D:\beam-dev\beam-anywhere-relay\bar\views.py", line 171, in post
    'Authorization': 'key=' + API_KEY,
TypeError: must be str, not dict
"POST /api/send_notification HTTP/1.1" 500 20187
"GET / HTTP/1.1" 200 865
Exception while resolving variable 'name' in template 'unknown'.
Traceback (most recent call last):
  File "D:\virtualenv\bar\lib\site-packages\django\core\handlers\exception.py", line 34, in inner
    response = get_response(request)
  File "D:\virtualenv\bar\lib\site-packages\django\core\handlers\base.py", line 111, in _get_response
    resolver_match = resolver.resolve(request.path_info)
  File "D:\virtualenv\bar\lib\site-packages\django\urls\resolvers.py", line 520, in resolve
    raise Resolver404({'tried': tried, 'path': new_path})
django.urls.exceptions.Resolver404: {'tried': [[<URLPattern '' [name='home']>], [<URLResolver <URLPattern list> (admin:admin) 'admin/'>], [<URLResolver <module 'bar.urls' from 'D:\\beam-dev\\beam-anywhere-relay\\bar\\urls.py'> (None:None) '^api/'>], [<URLPattern 'apple-app-site-association'>], [<URLPattern 'link_user'>]], 'path': 'explorer/blocks/'}

During handling of the above exception, another exception occurred:

Traceback (most recent call last):
  File "D:\virtualenv\bar\lib\site-packages\django\template\base.py", line 829, in _resolve_lookup
    current = current[bit]
TypeError: 'URLResolver' object is not subscriptable

During handling of the above exception, another exception occurred:

Traceback (most recent call last):
  File "D:\virtualenv\bar\lib\site-packages\django\template\base.py", line 837, in _resolve_lookup
    current = getattr(current, bit)
AttributeError: 'URLResolver' object has no attribute 'name'

During handling of the above exception, another exception occurred:

Traceback (most recent call last):
  File "D:\virtualenv\bar\lib\site-packages\django\template\base.py", line 843, in _resolve_lookup
    current = current[int(bit)]
ValueError: invalid literal for int() with base 10: 'name'

During handling of the above exception, another exception occurred:

Traceback (most recent call last):
  File "D:\virtualenv\bar\lib\site-packages\django\template\base.py", line 850, in _resolve_lookup
    (bit, current))  # missing attribute
django.template.base.VariableDoesNotExist: Failed lookup for key [name] in <URLResolver <URLPattern list> (admin:admin) 'admin/'>
Exception while resolving variable 'name' in template 'unknown'.
Traceback (most recent call last):
  File "D:\virtualenv\bar\lib\site-packages\django\core\handlers\exception.py", line 34, in inner
    response = get_response(request)
  File "D:\virtualenv\bar\lib\site-packages\django\core\handlers\base.py", line 111, in _get_response
    resolver_match = resolver.resolve(request.path_info)
  File "D:\virtualenv\bar\lib\site-packages\django\urls\resolvers.py", line 520, in resolve
    raise Resolver404({'tried': tried, 'path': new_path})
django.urls.exceptions.Resolver404: {'tried': [[<URLPattern '' [name='home']>], [<URLResolver <URLPattern list> (admin:admin) 'admin/'>], [<URLResolver <module 'bar.urls' from 'D:\\beam-dev\\beam-anywhere-relay\\bar\\urls.py'> (None:None) '^api/'>], [<URLPattern 'apple-app-site-association'>], [<URLPattern 'link_user'>]], 'path': 'explorer/status/'}

During handling of the above exception, another exception occurred:

Traceback (most recent call last):
  File "D:\virtualenv\bar\lib\site-packages\django\template\base.py", line 829, in _resolve_lookup
    current = current[bit]
TypeError: 'URLResolver' object is not subscriptable

During handling of the above exception, another exception occurred:

Traceback (most recent call last):
  File "D:\virtualenv\bar\lib\site-packages\django\template\base.py", line 837, in _resolve_lookup
    current = getattr(current, bit)
AttributeError: 'URLResolver' object has no attribute 'name'

During handling of the above exception, another exception occurred:

Traceback (most recent call last):
  File "D:\virtualenv\bar\lib\site-packages\django\template\base.py", line 843, in _resolve_lookup
    current = current[int(bit)]
ValueError: invalid literal for int() with base 10: 'name'

During handling of the above exception, another exception occurred:

Traceback (most recent call last):
  File "D:\virtualenv\bar\lib\site-packages\django\template\base.py", line 850, in _resolve_lookup
    (bit, current))  # missing attribute
django.template.base.VariableDoesNotExist: Failed lookup for key [name] in <URLResolver <URLPattern list> (admin:admin) 'admin/'>
Exception while resolving variable 'name' in template 'unknown'.
Traceback (most recent call last):
  File "D:\virtualenv\bar\lib\site-packages\django\core\handlers\exception.py", line 34, in inner
    response = get_response(request)
  File "D:\virtualenv\bar\lib\site-packages\django\core\handlers\base.py", line 111, in _get_response
    resolver_match = resolver.resolve(request.path_info)
  File "D:\virtualenv\bar\lib\site-packages\django\urls\resolvers.py", line 520, in resolve
    raise Resolver404({'tried': tried, 'path': new_path})
django.urls.exceptions.Resolver404: {'tried': [[<URLPattern '' [name='home']>], [<URLResolver <URLPattern list> (admin:admin) 'admin/'>], [<URLResolver <module 'bar.urls' from 'D:\\beam-dev\\beam-anywhere-relay\\bar\\urls.py'> (None:None) '^api/'>], [<URLPattern 'apple-app-site-association'>], [<URLPattern 'link_user'>]], 'path': 'explorer/blocks/'}

During handling of the above exception, another exception occurred:

Traceback (most recent call last):
  File "D:\virtualenv\bar\lib\site-packages\django\template\base.py", line 829, in _resolve_lookup
    current = current[bit]
TypeError: 'URLResolver' object is not subscriptable

During handling of the above exception, another exception occurred:

Traceback (most recent call last):
  File "D:\virtualenv\bar\lib\site-packages\django\template\base.py", line 837, in _resolve_lookup
    current = getattr(current, bit)
AttributeError: 'URLResolver' object has no attribute 'name'

During handling of the above exception, another exception occurred:

Traceback (most recent call last):
  File "D:\virtualenv\bar\lib\site-packages\django\template\base.py", line 843, in _resolve_lookup
    current = current[int(bit)]
ValueError: invalid literal for int() with base 10: 'name'

During handling of the above exception, another exception occurred:

Traceback (most recent call last):
  File "D:\virtualenv\bar\lib\site-packages\django\template\base.py", line 850, in _resolve_lookup
    (bit, current))  # missing attribute
django.template.base.VariableDoesNotExist: Failed lookup for key [name] in <URLResolver <module 'bar.urls' from 'D:\\beam-dev\\beam-anywhere-relay\\bar\\urls.py'> (None:None) '^api/'>
Exception while resolving variable 'name' in template 'unknown'.
Traceback (most recent call last):
  File "D:\virtualenv\bar\lib\site-packages\django\core\handlers\exception.py", line 34, in inner
    response = get_response(request)
  File "D:\virtualenv\bar\lib\site-packages\django\core\handlers\base.py", line 111, in _get_response
    resolver_match = resolver.resolve(request.path_info)
  File "D:\virtualenv\bar\lib\site-packages\django\urls\resolvers.py", line 520, in resolve
    raise Resolver404({'tried': tried, 'path': new_path})
django.urls.exceptions.Resolver404: {'tried': [[<URLPattern '' [name='home']>], [<URLResolver <URLPattern list> (admin:admin) 'admin/'>], [<URLResolver <module 'bar.urls' from 'D:\\beam-dev\\beam-anywhere-relay\\bar\\urls.py'> (None:None) '^api/'>], [<URLPattern 'apple-app-site-association'>], [<URLPattern 'link_user'>]], 'path': 'explorer/status/'}

During handling of the above exception, another exception occurred:

Traceback (most recent call last):
  File "D:\virtualenv\bar\lib\site-packages\django\template\base.py", line 829, in _resolve_lookup
    current = current[bit]
TypeError: 'URLResolver' object is not subscriptable

During handling of the above exception, another exception occurred:

Traceback (most recent call last):
  File "D:\virtualenv\bar\lib\site-packages\django\template\base.py", line 837, in _resolve_lookup
    current = getattr(current, bit)
AttributeError: 'URLResolver' object has no attribute 'name'

During handling of the above exception, another exception occurred:

Traceback (most recent call last):
  File "D:\virtualenv\bar\lib\site-packages\django\template\base.py", line 843, in _resolve_lookup
    current = current[int(bit)]
ValueError: invalid literal for int() with base 10: 'name'

During handling of the above exception, another exception occurred:

Traceback (most recent call last):
  File "D:\virtualenv\bar\lib\site-packages\django\template\base.py", line 850, in _resolve_lookup
    (bit, current))  # missing attribute
django.template.base.VariableDoesNotExist: Failed lookup for key [name] in <URLResolver <module 'bar.urls' from 'D:\\beam-dev\\beam-anywhere-relay\\bar\\urls.py'> (None:None) '^api/'>
Not Found: /explorer/blocks/
Not Found: /explorer/status/
"GET /explorer/blocks/?page=1 HTTP/1.1" 404 2460
"GET /explorer/status/ HTTP/1.1" 404 2453
(0.001) SELECT "bar_user"."id", "bar_user"."username", "bar_user"."user_id", "bar_user"."push_token", "bar_user"."wallet_address", "bar_user"."created_at", "bar_user"."msgr_type" FROM "bar_user" WHERE ("bar_user"."msgr_type" = 'tg' AND "bar_user"."user_id" = 123); args=('tg', 123)
(0.000) BEGIN; args=None
(0.001) INSERT INTO "bar_notification" ("transaction_status", "push_status", "send_from", "amount", "fee", "created_at", "updated_at", "push_type") VALUES ('initiated', 1, '123', 1, 1.0, '2019-05-06 15:57:52.145893', '2019-05-06 15:57:52.145893', 0); args=['initiated', 1, '123', 1, 1.0, '2019-05-06 15:57:52.145893', '2019-05-06 15:57:52.145893', 0]
Internal Server Error: /api/send_notification
Traceback (most recent call last):
  File "D:\virtualenv\bar\lib\site-packages\django\core\handlers\exception.py", line 34, in inner
    response = get_response(request)
  File "D:\virtualenv\bar\lib\site-packages\django\core\handlers\base.py", line 126, in _get_response
    response = self.process_exception_by_middleware(e, request)
  File "D:\virtualenv\bar\lib\site-packages\django\core\handlers\base.py", line 124, in _get_response
    response = wrapped_callback(request, *callback_args, **callback_kwargs)
  File "D:\virtualenv\bar\lib\site-packages\django\views\decorators\csrf.py", line 54, in wrapped_view
    return view_func(*args, **kwargs)
  File "D:\virtualenv\bar\lib\site-packages\django\views\generic\base.py", line 68, in view
    return self.dispatch(request, *args, **kwargs)
  File "D:\virtualenv\bar\lib\site-packages\rest_framework\views.py", line 495, in dispatch
    response = self.handle_exception(exc)
  File "D:\virtualenv\bar\lib\site-packages\rest_framework\views.py", line 455, in handle_exception
    self.raise_uncaught_exception(exc)
  File "D:\virtualenv\bar\lib\site-packages\rest_framework\views.py", line 492, in dispatch
    response = handler(request, *args, **kwargs)
  File "D:\beam-dev\beam-anywhere-relay\bar\views.py", line 171, in post
    'Authorization': 'key=' + API_KEY,
TypeError: must be str, not dict
"POST /api/send_notification HTTP/1.1" 500 20187
(0.000) 
            SELECT name, type FROM sqlite_master
            WHERE type in ('table', 'view') AND NOT name='sqlite_sequence'
            ORDER BY name; args=None
(0.000) SELECT "django_migrations"."app", "django_migrations"."name" FROM "django_migrations"; args=()
(0.000) SELECT "bar_user"."id", "bar_user"."username", "bar_user"."user_id", "bar_user"."push_token", "bar_user"."wallet_address", "bar_user"."created_at", "bar_user"."msgr_type" FROM "bar_user" WHERE ("bar_user"."msgr_type" = 'tg' AND "bar_user"."user_id" = 123); args=('tg', 123)
(0.000) BEGIN; args=None
(0.001) INSERT INTO "bar_notification" ("transaction_status", "push_status", "send_from", "amount", "fee", "created_at", "updated_at", "push_type") VALUES ('initiated', 1, '123', 1, 1.0, '2019-05-06 15:58:26.533850', '2019-05-06 15:58:26.533850', 0); args=['initiated', 1, '123', 1, 1.0, '2019-05-06 15:58:26.533850', '2019-05-06 15:58:26.533850', 0]
"POST /api/send_notification HTTP/1.1" 200 32
(0.001) 
            SELECT name, type FROM sqlite_master
            WHERE type in ('table', 'view') AND NOT name='sqlite_sequence'
            ORDER BY name; args=None
(0.000) SELECT "django_migrations"."app", "django_migrations"."name" FROM "django_migrations"; args=()
